Workbook
Name ScenID: #REF!
Name Selected_Scenario: 'Scenario Manager'!#REF!

Sheet Cover
A1: INDUSTRY FINANCIAL MODEL
A2: INDIAN STEEL INDUSTRY
A4: Indian Steel Industry Research & Valuation Model
A5: Forecast horizon FY2027E-FY2033E (7 years) | Base year FY2026A
A7: An integrated financial modelling platform for analysing the Indian steel industry.
A8: This workbook integrates macroeconomic forecasting, industry demand and supply modelling, capacity expansion, pricing, raw material economics, profitability, cash flow, valuation and scenario analysis into a single dynamic platform designed for institutional investment research and company valuation.
A9: Designed to support equity research, investment banking, corporate finance, private equity and individual company valuation.
A11: Coverage Universe | D11: Model Information | G11: Data Sources
A12: Core Coverage | B12: Supporting Coverage | D12: Field | E12: Value | G12: Primary Sources | H12: Industry Sources
A13: Tata Steel | B13: AM/NS India | D13: Industry | E13: Steel | G13: Annual Reports | H13: World Steel Association
A14: JSW Steel | B14: RINL (Vizag Steel) | D14: Version | E14: 1 | G14: Quarterly Results | H14: Joint Plant Committee
A15: SAIL | B15: Shyam Metalics | D15: Base Year | E15: FY2026A | G15: Investor Presentations | H15: Ministry of Steel
A16: Jindal Steel | B16: Godawari Power | D16: Forecast | E16: FY2027E–FY2033E | G16: Exchange Filings | H16: OECD
A17: Jindal Stainless | B17: APL Apollo | D17: Forecast Horizon | E17: 7 Years | H17: DGFT
B18: Kirloskar Ferrous | D18: Currency | E18: INR | H18: RBI
B19: Others - secondary | D19: Reporting Basis | E19: Consolidated | H19: IMF
D20: Last Upload | E20: 46237 | H20: World Bank
A25: Prepared By : Om Prakash Panda
A26: Confidential For Educational & Research Purposes
A28: Internal analytical model prepared solely for research and valuation purposes. Figures are derived from publicly available information and analyst assumptions. Not intended for public distribution.

Sheet Index
A1: INDEX
A2: Click a sheet name to navigate.
A4: No | B4: Worksheet | C4: Category | D4: Description
A5: Project Administration
A6: C | B6: Cover | C6: Information | D6: Workbook cover page
A7: 0 | B7: Database Import | C7: Input | D7: Import data from Master Industry Database
A8: 0H | B8: Forecast Horizon | C8: Documentation | D8: Forecast horizon selection
A9: Model Control
A10: 1 | B10: Control Panel | C10: Control | D10: Model settings and scenario selection
A11: =A10+1 | B11: Model Assumptions | C11: Input | D11: Global modelling assumptions
A12: =A11+1 | B12: Model Calibration | C12: Input | D12: Benchmark values and calibration variables
A13: Core Industry Models
A14: =A12+1 | B14: Macroeconomic Model | C14: Model | D14: Economic forecasts
A15: =A14+1 | B15: Steel Demand Model | C15: Model | D15: Industry demand forecast
A16: =A15+1 | B16: Steel Supply Model | C16: Model | D16: Industry supply forecast
A17: =A16+1 | B17: Capacity Forecast | C17: Model | D17: Installed capacity forecast
A18: =A17+1 | B18: Capacity Expansion Tracker | C18: Input | D18: Capacity additions
A19: =A18+1 | B19: Capacity Utilisation | C19: Model | D19: Utilisation analysis
A20: =A19+1 | B20: Steel Price Forecast | C20: Model | D20: Steel price forecast
A21: =A20+1 | B21: Raw Material Forecast | C21: Model | D21: Raw material forecast
A22: =A21+1 | B22: Cost Curve | C22: Model | D22: Industry cost position
A23: =A22+1 | B23: Revenue Forecast | C23: Model | D23: Forecast Industry Revenue
A24: =A23+1 | B24: EBITDA Model | C24: Model | D24: Forecast Profitability
A25: =A24+1 | B25: Margin Analysis | C25: Model | D25: Margin analysis
A26: =A25+1 | B26: Working Capital Model | C26: Model | D26: Working capital forecast
... A31: =A30+1 | B31: ESG Model | C31: Model | D31: Sustainability analysis
A32: Outputs
A33: =A31+1 | B33: Scenario Manager | C33: Output | D33: Scenario comparison
A34: =A33+1 | B34: Sensitivity Analysis | C34: Output | D34: Sensitivity testing
A35: =A34+1 | B35: Comparable Valuation | C35: Output | D35: Sector valuation
A36: =A35+1 | B36: Industry Dashboard | C36: Output | D36: Executive dashboard
A37: Validation & Documentation
A38: =A36+1 | B38: Audit Checks | C38: Audit | D38: Model validation
A39: =A38+1 | B39: Sources | C39: Documentation | D39: References and source log
A42: 🟦 Input
A43: ⬛ Formula
A44: 🟩 External Link
A45: 🟥 External Workbook
A46: 🟧 Missing Data

Sheet Database Import
A1: DATABASE IMPORT
A2: Industry Financial Model | Indian Steel Industry | Horizon FY2027E-FY2033E | Base year FY2026A
A4: Workbook Information
A5: Field | B5: Value
A6: Source Workbook | B6: Master Industry Database.xlsx
A7: Workbook Version | B7: 1
A8: Last Updated | B8: Linked
A9: Reporting Basis | B9: Consolidated
A10: Currency | B10: INR
A11: Coverage Universe | B11: 5 Companies
A12: Historical Period | B12: FY2021–FY2026
A13: Import Status | B13: ✅ Connected
A16: Data Quality Checks
A17: Dataset | B17: Dataset
A18: Duplicate Companies | B18: ✅
A19: Missing Financial Years | B19: ✅
A20: Missing Capacity Data | B20: ✅
A21: Missing Revenue Data | B21: ✅
A22: Missing EBITDA Data | B22: ✅
A23: Missing Price Series | B23: ✅
A24: Currency Consistent | B24: ✅
A25: Units Consistent | B25: ✅
A29: Data Flow Diagram
A30: Master Industry Database
A31: │
A32: ▼
A33: Database Import
A34: │
A35: ▼
A36: Model Assumptions
A37: │
A38: ▼
A39: Industry Models
A40: │
... A49: Purpose: This worksheet serves as the controlled interface between the Master Industry Database and the Industry Financial Model. No manual analytical inputs or calculations should be performed on this sheet. All imported datasets are validated before being used by downstream models.

Sheet Forecast Horizon
A1: FORECAST HORIZON
A2: Industry Financial Model | Indian Steel Industry | Horizon FY2027E-FY2033E | Base year FY2026A
A4: Forecast Horizon Decision
A5: Field | B5: Value
A6: Historical Period | B6: FY2021A – FY2026A
A7: Forecast Period | B7: FY2027E – FY2033E
A8: Forecast Horizon | B8: 7 Years
A9: Base Year | B9: FY2026A
A10: Terminal Year | B10: FY2033E
A13: Horizon Comparison
A14: Criterion | B14: Weight | C14: 5-Year (FY2027-FY2031) | D14: 7-Year (FY2027-FY2033) | E14: 10-Year (FY2027-FY2036) | F14: Score 5Y | G14: Score 7Y | H14: Score 10Y | I14: Basis of assessment / evidence | J14: Audit Code
A15: Coverage of the announced capacity pipeline | B15: 0.25 | C15: Ends FY2031, exactly the terminal year of the announced pipeline. Captures 100% of commissioning but 0 years of post-commissioning ramp. | D15: Ends FY2033. Captures 100% of commissioning PLUS a 2-year ramp tail, so the terminal year reflects normalised rather than ramping utilisation. | E15: Ends FY2036, five years beyond the last dated project. Years 8-10 have no project-level visibility and become pure extrapolation. | F15: 3 | G15: 5 | H15: 2 | I15: Dated pipeline in the Master Database terminates FY2031: POSCO-JSW 6 Mtpa greenfield by 2031, SAIL ~35 Mt ambition by FY2031, PLI 1.2 capacity 8.7 Mt by FY2031, National Steel Policy 2017 target year FY2031. No credible dated project extends beyond FY2031.
A16: Terminal year is a normalised, valuation-usable year | B16: 0.25 | C16: NO. Capacity commissioned FY2030-FY2031 is still ramping in FY2031, so terminal-year utilisation is artificially depressed and a terminal value struck there is understated. | D16: YES. The FY2030-FY2031 capacity cohort reaches normalised utilisation by FY2033 on a 2-3 year ramp, so the terminal year is a fair steady state. | E16: YES but redundant - steady state is already reached by FY2033, so FY2034-FY2036 add extrapolation risk without adding information. | F16: 1 | G16: 5 | H16: 4 | I16: Greenfield and large brownfield Indian steel capacity historically takes 2-3 years from commissioning to normalised utilisation. Observed in the database: NMDC Steel Nagarnar (3 Mtpa) produced 1.471 Mt in FY2025 and 2.382 Mt in FY2026, i.e. ~79% of nameplate in year 3+; RINL required a full year to recover to 5.43 Mt.
A17: Coverage of a complete industry cycle | B17: 0.2 | C17: ~0.7 cycles. Truncates the cycle, so the average forecast year is not cycle-neutral and the result is highly sensitive to where the start point sits in the cycle. | D17: ~1.0 cycle. The forecast average is approximately cycle-neutral, which is the property a mid-cycle valuation requires. | E17: ~1.4 cycles. Cycle-neutral but the second partial cycle is unforecastable in its timing. | F17: 2 | G17: 5 | H17: 3 | I17: Observed cycle length in the database: standardised EBITDA margin for Tata Steel peaked at 26% in FY2022, troughed at 10% in FY2024 and recovered to 15% in FY2026 - a 4-year peak-to-trough leg implying a ~7-8 year full cycle. Coking coal peaked at US$354/t in Oct-2023 and troughed at ~US$175/t in Mar-2025; iron ore peaked at US$155.52/dmt in FY2022 and troughed at US$100.52/dmt in FY2026.
A18: Reliability of the macro anchor | B18: 0.15 | C18: Strong. RBI publishes an explicit FY2027 projection and the IMF medium-term path is credible to roughly 5 years. | D18: Adequate. Years 6-7 rely on a converging steady-state growth assumption rather than a published projection, which is disclosed and sensitised. | E18: Weak. Years 8-10 require a GDP path with no institutional publisher support at all. | F18: 5 | G18: 4 | H18: 2 | I18: RBI's June-2026 MPC projects FY2027 real GDP growth at 6.6%. No official Indian source publishes a real GDP path beyond roughly 5 years, so any year past FY2031 is the modeller's own convergence assumption.
A19: Usability for DCF terminal value | B19: 0.15 | C19: Poor. A terminal value struck on a non-normalised year requires a manual mid-cycle adjustment, which defeats the purpose of an explicit forecast period. | D19: Good. Terminal value can be struck directly off FY2033 with no manual normalisation. | E19: Good but the incremental years add estimation error to the discounted stub, where their present-value weight is small. | F19: 2 | G19: 5 | H19: 3 | I19: At a ~12% nominal WACC the present-value weight of forecast years 8-10 is under 12% of total enterprise value, so extending the horizon adds materially more estimation error than valuation information.
A20: WEIGHTED TOTAL | B20: =SUM(B15:B19) | F20: =SUMPRODUCT($B$15:$B$19,F15:F19) | G20: =SUMPRODUCT($B$15:$B$19,G15:G19) | H20: =SUMPRODUCT($B$15:$B$19,H15:H19) | I20: Live formula. The 7-year option wins on four of five criteria and ties on none; it loses only on macro-anchor reliability, where the 5-year option is stronger. | J20: FH01
A23: Scope
A24: This model forecasts:
A25: Steel demand
A26: Steel supply
A27: Installed capacity
A28: Capacity utilisation
A29: Steel prices
A30: Raw material prices
A31: Revenue
A32: EBITDA
A33: Margins
A34: Working capital
... A39: Review Policy
A40: Item | B40: Frequency
A41: Forecast Horizon | B41: Annual
A42: Base Year Roll Forward | B42: Annual
A43: Historical Data Update | B43: Quarterly
A44: Assumption Review | B44: Quarterly
A45: Full Model Review | B45: Annual
A48: FY21A FY22A FY23A FY24A FY25A FY26A | FY27E FY28E FY29E FY30E FY31E FY32E FY33E
A49: Historical (Actual) | Forecast

Sheet Control Panel
A1: CONTROL PANEL
A2: Industry Financial Model | Indian Steel Industry | Horizon FY2027E-FY2033E | Base year FY2026A
A4: Model Information | D4: Global Controls | G4: Workbook Status
A5: Parameter | B5: Value | D5: Settings | E5: Value | G5: Check | H5: Status
A6: Model Name | B6: Indian Steel Industry Financial Model | D6: Scenario | E6: =E17 | G6: Database Connected | H6: =IF(COUNT('Model Calibration'!$D$10:$D$14)=5,"OK","CHECK")
A7: Version | B7: 1 | D7: Currency Display | E7: INR | G7: Assumptions Complete | H7: =IF(COUNT('Model Assumptions'!$E$8:$K$33)=182,"OK","CHECK")
A8: Status | B8: Final | D8: Number Format | E8: Crore | G8: Calibration Complete | H8: =IF(AND(ISNUMBER('Model Calibration'!$D$19),ISNUMBER('Model Calibration'!$D$21),ABS('Model Calibration'!$D$19-'Model Calibration'!$D$21-'Model Calibration'!$D$20)<1),"OK","CHECK")
A9: Last Uploaded | B9: =TODAY() | D9: Forecast Year | E9: 7 | G9: Forecast Built | H9: =IF(COUNT('EBITDA Model'!$D$103:$J$103)=7,"OK","CHECK")
A10: Base Year | B10: FY2026A | D10: Steel Price Basis | E10: Domestic | G10: Dashboard Updated | H10: =IF(COUNT('Industry Dashboard'!$D$32:$J$32)=7,"OK","CHECK")
A11: Forecast Horizon | B11: FY2027E-FY2033E | D11: Inflation Basis | E11: CPI
A12: Currency | B12: INR
A13: Reporting Basis | B13: Consolidated
A16: Quick Navigation | D16: SCENARIO SELECTOR
A17: Module | B17: Link | D17: Active scenario | E17: Base Case
A18: Database Import | B18: Go → | D18: Scenario Index | E18: =MATCH(E$17,E$20:E$23,0)
A19: Model Assumptions | B19: Go →
A20: Model Calibration | B20: Go → | D20: 1. | E20: Base Case | F20: Central case. RBI FY2027 GDP of 6.6%, realisation calibrated to a FY2033 industry margin of 16.8%.
A21: Macro Model | B21: Go → | D21: 2. | E21: Bull Case | F21: Demand-led upcycle. Peaks at a 26.0% industry margin in FY2030, matching the FY2022 cycle peak.
A22: Demand Model | B22: Go → | D22: 3. | E22: Bear Case | F22: Demand-led downturn. Raw materials FALL with demand, so margins compress to 7-11% rather than collapsing.
A23: Supply Model | B23: Go → | D23: 4. | E23: Stress Case | F23: Stagflationary supply shock plus demand shock. Coking coal to US$300/t, INR to 113. Troughs at -9.2% in FY2028.
A24: Capacity Model | B24: Go →
A25: Price Model | B25: Go →
A26: Revenue Model | B26: Go →
A27: EBITDA Model | B27: Go →
A28: Valuation | B28: Go →
A29: Dashboard | B29: Go →
A30: Audit | B30: Go →
A31: Sources | B31: Go →
A34: LIVE MODEL OUTPUT - ACTIVE SCENARIO
A35: Line item | B35: Unit | C35: FY2026A | D35: FY2027E | E35: FY2028E | F35: FY2029E | G35: FY2030E | H35: FY2031E | I35: FY2032E | J35: FY2033E | K35: CAGR | L35: Audit Code | M35: Source
A36: India finished steel consumption | B36: Mt | C36: ='Steel Demand Model'!C$75 | D36: ='Steel Demand Model'!D$75 | E36: ='Steel Demand Model'!E$75 | F36: ='Steel Demand Model'!F$75 | G36: ='Steel Demand Model'!G$75 | H36: ='Steel Demand Model'!H$75 | I36: ='Steel Demand Model'!I$75 | J36: ='Steel Demand Model'!J$75 | K36: =IFERROR(IF(AND(ISNUMBER(C36),ISNUMBER(J36),C36>0),(J36/C36)^(1/7)-1,""),"") | L36: CP01 | M36: 04
A37: India crude steel production | B37: Mt | C37: ='Steel Supply Model'!C$88 | D37: ='Steel Supply Model'!D$88 | E37: ='Steel Supply Model'!E$88 | F37: ='Steel Supply Model'!F$88 | G37: ='Steel Supply Model'!G$88 | H37: ='Steel Supply Model'!H$88 | I37: ='Steel Supply Model'!I$88 | J37: ='Steel Supply Model'!J$88 | K37: =IFERROR(IF(AND(ISNUMBER(C37),ISNUMBER(J37),C37>0),(J37/C37)^(1/7)-1,""),"") | L37: CP02 | M37: 05
A38: India crude steel capacity | B38: Mtpa | C38: ='Capacity Forecast'!C$96 | D38: ='Capacity Forecast'!D$96 | E38: ='Capacity Forecast'!E$96 | F38: ='Capacity Forecast'!F$96 | G38: ='Capacity Forecast'!G$96 | H38: ='Capacity Forecast'!H$96 | I38: ='Capacity Forecast'!I$96 | J38: ='Capacity Forecast'!J$96 | K38: =IFERROR(IF(AND(ISNUMBER(C38),ISNUMBER(J38),C38>0),(J38/C38)^(1/7)-1,""),"") | L38: CP03 | M38: 06
A39: Capacity utilisation | B39: % | C39: ='Capacity Utilisation'!C$65 | D39: ='Capacity Utilisation'!D$65 | E39: ='Capacity Utilisation'!E$65 | F39: ='Capacity Utilisation'!F$65 | G39: ='Capacity Utilisation'!G$65 | H39: ='Capacity Utilisation'!H$65 | I39: ='Capacity Utilisation'!I$65 | J39: ='Capacity Utilisation'!J$65 | K39: =IFERROR(IF(AND(ISNUMBER(C39),ISNUMBER(J39),C39>0),(J39/C39)^(1/7)-1,""),"") | L39: CP04 | M39: 08
A40: Blended realisation | B40: Rs/t | C40: ='Steel Price Forecast'!C$72 | D40: ='Steel Price Forecast'!D$72 | E40: ='Steel Price Forecast'!E$72 | F40: ='Steel Price Forecast'!F$72 | G40: ='Steel Price Forecast'!G$72 | H40: ='Steel Price Forecast'!H$72 | I40: ='Steel Price Forecast'!I$72 | J40: ='Steel Price Forecast'!J$72 | K40: =IFERROR(IF(AND(ISNUMBER(C40),ISNUMBER(J40),C40>0),(J40/C40)^(1/7)-1,""),"") | L40: CP05 | M40: 09
A41: Cash cost per tonne | B41: Rs/t | C41: ='Cost Curve'!C$65 | D41: ='Cost Curve'!D$65 | E41: ='Cost Curve'!E$65 | F41: ='Cost Curve'!F$65 | G41: ='Cost Curve'!G$65 | H41: ='Cost Curve'!H$65 | I41: ='Cost Curve'!I$65 | J41: ='Cost Curve'!J$65 | K41: =IFERROR(IF(AND(ISNUMBER(C41),ISNUMBER(J41),C41>0),(J41/C41)^(1/7)-1,""),"") | L41: CP06 | M41: 11
A42: EBITDA per tonne | B42: Rs/t | C42: ='EBITDA Model'!C$101 | D42: ='EBITDA Model'!D$101 | E42: ='EBITDA Model'!E$101 | F42: ='EBITDA Model'!F$101 | G42: ='EBITDA Model'!G$101 | H42: ='EBITDA Model'!H$101 | I42: ='EBITDA Model'!I$101 | J42: ='EBITDA Model'!J$101 | K42: =IFERROR(IF(AND(ISNUMBER(C42),ISNUMBER(J42),C42>0),(J42/C42)^(1/7)-1,""),"") | L42: CP07 | M42: 13
A43: Industry EBITDA margin | B43: % | C43: ='Margin Analysis'!C$81 | D43: ='Margin Analysis'!D$81 | E43: ='Margin Analysis'!E$81 | F43: ='Margin Analysis'!F$81 | G43: ='Margin Analysis'!G$81 | H43: ='Margin Analysis'!H$81 | I43: ='Margin Analysis'!I$81 | J43: ='Margin Analysis'!J$81 | K43: =IFERROR(IF(AND(ISNUMBER(C43),ISNUMBER(J43),C43>0),(J43/C43)^(1/7)-1,""),"") | L43: CP08 | M43: 14
A44: Industry revenue | B44: Rs cr | C44: ='Revenue Forecast'!C$95 | D44: ='Revenue Forecast'!D$95 | E44: ='Revenue Forecast'!E$95 | F44: ='Revenue Forecast'!F$95 | G44: ='Revenue Forecast'!G$95 | H44: ='Revenue Forecast'!H$95 | I44: ='Revenue Forecast'!I$95 | J44: ='Revenue Forecast'!J$95 | K44: =IFERROR(IF(AND(ISNUMBER(C44),ISNUMBER(J44),C44>0),(J44/C44)^(1/7)-1,""),"") | L44: CP09 | M44: 12
A45: Industry EBITDA | B45: Rs cr | C45: ='EBITDA Model'!C$103 | D45: ='EBITDA Model'!D$103 | E45: ='EBITDA Model'!E$103 | F45: ='EBITDA Model'!F$103 | G45: ='EBITDA Model'!G$103 | H45: ='EBITDA Model'!H$103 | I45: ='EBITDA Model'!I$103 | J45: ='EBITDA Model'!J$103 | K45: =IFERROR(IF(AND(ISNUMBER(C45),ISNUMBER(J45),C45>0),(J45/C45)^(1/7)-1,""),"") | L45: CP10 | M45: 13
...

Sheet Model Assumptions
A1: MODEL ASSUMPTIONS
A2: Industry Financial Model | Indian Steel Industry | Horizon FY2027E-FY2033E | Base year FY2026A
A4: Running Scenario | C4: ='Control Panel'!E17
A6: ACTIVE DRIVERS
A7: No | B7: Line item | C7: Unit | D7: FY2026A | E7: FY2027E | F7: FY2028E | G7: FY2029E | H7: FY2030E | I7: FY2031E | J7: FY2032E | K7: FY2033E | L7: Source | M7: Conf.
A8: D01 | B8: India real GDP growth | C8: % | D8: =[1]Macroeconomic!$H$6 | E8: =_xlfn.XLOOKUP($C$4,$D$38:$D$41,E38:E41) | F8: =_xlfn.XLOOKUP($C$4,$D$38:$D$41,F38:F41) | G8: =_xlfn.XLOOKUP($C$4,$D$38:$D$41,G38:G41) | H8: =_xlfn.XLOOKUP($C$4,$D$38:$D$41,H38:H41) | I8: =_xlfn.XLOOKUP($C$4,$D$38:$D$41,I38:I41) | J8: =_xlfn.XLOOKUP($C$4,$D$38:$D$41,J38:J41) | K8: =_xlfn.XLOOKUP($C$4,$D$38:$D$41,K38:K41) | L8: RBI-Jun26 | M8: High
A9: D02 | B9: Steel demand elasticity to real GDP | C9: x | D9: =[1]Macroeconomic!$H$11 | E9: =_xlfn.XLOOKUP($C$4,$D$42:$D$45,E42:E45) | F9: =_xlfn.XLOOKUP($C$4,$D$42:$D$45,F42:F45) | G9: =_xlfn.XLOOKUP($C$4,$D$42:$D$45,G42:G45) | H9: =_xlfn.XLOOKUP($C$4,$D$42:$D$45,H42:H45) | I9: =_xlfn.XLOOKUP($C$4,$D$42:$D$45,I42:I45) | J9: =_xlfn.XLOOKUP($C$4,$D$42:$D$45,J42:J45) | K9: =_xlfn.XLOOKUP($C$4,$D$42:$D$45,K42:K45) | L9: Derived-DB | M9: High
A10: D03 | B10: USD/INR average | C10: Rs/US$ | D10: =[1]Macroeconomic!$H$8 | E10: =_xlfn.XLOOKUP($C$4,$D$46:$D$49,E46:E49) | F10: =_xlfn.XLOOKUP($C$4,$D$46:$D$49,F46:F49) | G10: =_xlfn.XLOOKUP($C$4,$D$46:$D$49,G46:G49) | H10: =_xlfn.XLOOKUP($C$4,$D$46:$D$49,H46:H49) | I10: =_xlfn.XLOOKUP($C$4,$D$46:$D$49,I46:I49) | J10: =_xlfn.XLOOKUP($C$4,$D$46:$D$49,J46:J49) | K10: =_xlfn.XLOOKUP($C$4,$D$46:$D$49,K46:K49) | L10: IDBI-22Jun26 | M10: High
A11: D04 | B11: CPI inflation | C11: % | D11: =[1]Macroeconomic!$H$7 | E11: =_xlfn.XLOOKUP($C$4,$D$50:$D$53,E50:E53) | F11: =_xlfn.XLOOKUP($C$4,$D$50:$D$53,F50:F53) | G11: =_xlfn.XLOOKUP($C$4,$D$50:$D$53,G50:G53) | H11: =_xlfn.XLOOKUP($C$4,$D$50:$D$53,H50:H53) | I11: =_xlfn.XLOOKUP($C$4,$D$50:$D$53,I50:I53) | J11: =_xlfn.XLOOKUP($C$4,$D$50:$D$53,J50:J53) | K11: =_xlfn.XLOOKUP($C$4,$D$50:$D$53,K50:K53) | L11: RBI-Jun26 | M11: High
A12: D05 | B12: Announced pipeline delivery factor | C12: % | D12: ='[1]Production Volume'!$H$10 | E12: =_xlfn.XLOOKUP($C$4,$D$54:$D$57,E54:E57) | F12: =_xlfn.XLOOKUP($C$4,$D$54:$D$57,F54:F57) | G12: =_xlfn.XLOOKUP($C$4,$D$54:$D$57,G54:G57) | H12: =_xlfn.XLOOKUP($C$4,$D$54:$D$57,H54:H57) | I12: =_xlfn.XLOOKUP($C$4,$D$54:$D$57,I54:I57) | J12: =_xlfn.XLOOKUP($C$4,$D$54:$D$57,J54:J57) | K12: =_xlfn.XLOOKUP($C$4,$D$54:$D$57,K54:K57) | L12: Derived-DB | M12: Medium
A13: D06 | B13: Crude-to-finished steel ratio | C13: x | D13: ='[1]Production Volume'!$H$11 | E13: =_xlfn.XLOOKUP($C$4,$D$58:$D$61,E58:E61) | F13: =_xlfn.XLOOKUP($C$4,$D$58:$D$61,F58:F61) | G13: =_xlfn.XLOOKUP($C$4,$D$58:$D$61,G58:G61) | H13: =_xlfn.XLOOKUP($C$4,$D$58:$D$61,H58:H61) | I13: =_xlfn.XLOOKUP($C$4,$D$58:$D$61,I58:I61) | J13: =_xlfn.XLOOKUP($C$4,$D$58:$D$61,J58:J61) | K13: =_xlfn.XLOOKUP($C$4,$D$58:$D$61,K58:K61) | L13: Derived-DB | M13: High
A14: D07 | B14: Net finished steel exports | C14: Mt | D14: ='[1]Imports & Exports'!$H$8 | E14: =_xlfn.XLOOKUP($C$4,$D$62:$D$65,E62:E65) | F14: =_xlfn.XLOOKUP($C$4,$D$62:$D$65,F62:F65) | G14: =_xlfn.XLOOKUP($C$4,$D$62:$D$65,G62:G65) | H14: =_xlfn.XLOOKUP($C$4,$D$62:$D$65,H62:H65) | I14: =_xlfn.XLOOKUP($C$4,$D$62:$D$65,I62:I65) | J14: =_xlfn.XLOOKUP($C$4,$D$62:$D$65,J62:J65) | K14: =_xlfn.XLOOKUP($C$4,$D$62:$D$65,K62:K65) | L14: Derived-DB | M14: Medium
A15: D08 | B15: Variation in stock | C15: Mt | D15: ='[1]Demand & Consumption'!$H$9 | E15: =_xlfn.XLOOKUP($C$4,$D$66:$D$69,E66:E69) | F15: =_xlfn.XLOOKUP($C$4,$D$66:$D$69,F66:F69) | G15: =_xlfn.XLOOKUP($C$4,$D$66:$D$69,G66:G69) | H15: =_xlfn.XLOOKUP($C$4,$D$66:$D$69,H66:H69) | I15: =_xlfn.XLOOKUP($C$4,$D$66:$D$69,I66:I69) | J15: =_xlfn.XLOOKUP($C$4,$D$66:$D$69,J66:J69) | K15: =_xlfn.XLOOKUP($C$4,$D$66:$D$69,K66:K69) | L15: Derived-DB | M15: Medium
A16: D09 | B16: Blended industry realisation | C16: Rs/t | D16: ='[1]Steel Prices'!$H$12 | E16: =_xlfn.XLOOKUP($C$4,$D$70:$D$73,E70:E73) | F16: =_xlfn.XLOOKUP($C$4,$D$70:$D$73,F70:F73) | G16: =_xlfn.XLOOKUP($C$4,$D$70:$D$73,G70:G73) | H16: =_xlfn.XLOOKUP($C$4,$D$70:$D$73,H70:H73) | I16: =_xlfn.XLOOKUP($C$4,$D$70:$D$73,I70:I73) | J16: =_xlfn.XLOOKUP($C$4,$D$70:$D$73,J70:J73) | K16: =_xlfn.XLOOKUP($C$4,$D$70:$D$73,K70:K73) | L16: Derived-DB | M16: Medium
A17: D10 | B17: Iron ore 62% Fe CFR China | C17: US$/dmt | D17: ='[1]Raw Materials'!$H$6 | E17: =_xlfn.XLOOKUP($C$4,$D$74:$D$77,E74:E77) | F17: =_xlfn.XLOOKUP($C$4,$D$74:$D$77,F74:F77) | G17: =_xlfn.XLOOKUP($C$4,$D$74:$D$77,G74:G77) | H17: =_xlfn.XLOOKUP($C$4,$D$74:$D$77,H74:H77) | I17: =_xlfn.XLOOKUP($C$4,$D$74:$D$77,I74:I77) | J17: =_xlfn.XLOOKUP($C$4,$D$74:$D$77,J74:J77) | K17: =_xlfn.XLOOKUP($C$4,$D$74:$D$77,K74:K77) | L17: S17 | M17: High
A18: D11 | B18: Premium HCC coking coal FOB Australia | C18: US$/t | D18: ='[1]Raw Materials'!$H$11 | E18: =_xlfn.XLOOKUP($C$4,$D$78:$D$81,E78:E81) | F18: =_xlfn.XLOOKUP($C$4,$D$78:$D$81,F78:F81) | G18: =_xlfn.XLOOKUP($C$4,$D$78:$D$81,G78:G81) | H18: =_xlfn.XLOOKUP($C$4,$D$78:$D$81,H78:H81) | I18: =_xlfn.XLOOKUP($C$4,$D$78:$D$81,I78:I81) | J18: =_xlfn.XLOOKUP($C$4,$D$78:$D$81,J78:J81) | K18: =_xlfn.XLOOKUP($C$4,$D$78:$D$81,K78:K81) | L18: S01 | M18: Medium
A19: D12 | B19: Conversion cost inflation | C19: % | D19: 0.05 | E19: =_xlfn.XLOOKUP($C$4,$D$82:$D$85,E82:E85) | F19: =_xlfn.XLOOKUP($C$4,$D$82:$D$85,F82:F85) | G19: =_xlfn.XLOOKUP($C$4,$D$82:$D$85,G82:G85) | H19: =_xlfn.XLOOKUP($C$4,$D$82:$D$85,H82:H85) | I19: =_xlfn.XLOOKUP($C$4,$D$82:$D$85,I82:I85) | J19: =_xlfn.XLOOKUP($C$4,$D$82:$D$85,J82:J85) | K19: =_xlfn.XLOOKUP($C$4,$D$82:$D$85,K82:K85) | L19: RBI-Jun26 | M19: Medium
A20: D13 | B20: Raw material share of cash cost | C20: % | D20: ='[1]Raw Materials'!$H$29 | E20: =_xlfn.XLOOKUP($C$4,$D$86:$D$89,E86:E89) | F20: =_xlfn.XLOOKUP($C$4,$D$86:$D$89,F86:F89) | G20: =_xlfn.XLOOKUP($C$4,$D$86:$D$89,G86:G89) | H20: =_xlfn.XLOOKUP($C$4,$D$86:$D$89,H86:H89) | I20: =_xlfn.XLOOKUP($C$4,$D$86:$D$89,I86:I89) | J20: =_xlfn.XLOOKUP($C$4,$D$86:$D$89,J86:J89) | K20: =_xlfn.XLOOKUP($C$4,$D$86:$D$89,K86:K89) | L20: Indicative | M20: Low
A21: D14 | B21: Iron ore weight in the raw material basket | C21: % | D21: ='[1]Raw Materials'!$H$30 | E21: =_xlfn.XLOOKUP($C$4,$D$90:$D$93,E90:E93) | F21: =_xlfn.XLOOKUP($C$4,$D$90:$D$93,F90:F93) | G21: =_xlfn.XLOOKUP($C$4,$D$90:$D$93,G90:G93) | H21: =_xlfn.XLOOKUP($C$4,$D$90:$D$93,H90:H93) | I21: =_xlfn.XLOOKUP($C$4,$D$90:$D$93,I90:I93) | J21: =_xlfn.XLOOKUP($C$4,$D$90:$D$93,J90:J93) | K21: =_xlfn.XLOOKUP($C$4,$D$90:$D$93,K90:K93) | L21: Indicative | M21: Low
A22: D15 | B22: Effective tax rate | C22: % | D22: 0.2517 | E22: =_xlfn.XLOOKUP($C$4,$D$94:$D$97,E94:E97) | F22: =_xlfn.XLOOKUP($C$4,$D$94:$D$97,F94:F97) | G22: =_xlfn.XLOOKUP($C$4,$D$94:$D$97,G94:G97) | H22: =_xlfn.XLOOKUP($C$4,$D$94:$D$97,H94:H97) | I22: =_xlfn.XLOOKUP($C$4,$D$94:$D$97,I94:I97) | J22: =_xlfn.XLOOKUP($C$4,$D$94:$D$97,J94:J97) | K22: =_xlfn.XLOOKUP($C$4,$D$94:$D$97,K94:K97) | L22: Statutory | M22: Medium
A23: D16 | B23: Capex intensity | C23: Rs/t of capacity added | D23: 55000 | E23: =_xlfn.XLOOKUP($C$4,$D$98:$D$101,E98:E101) | F23: =_xlfn.XLOOKUP($C$4,$D$98:$D$101,F98:F101) | G23: =_xlfn.XLOOKUP($C$4,$D$98:$D$101,G98:G101) | H23: =_xlfn.XLOOKUP($C$4,$D$98:$D$101,H98:H101) | I23: =_xlfn.XLOOKUP($C$4,$D$98:$D$101,I98:I101) | J23: =_xlfn.XLOOKUP($C$4,$D$98:$D$101,J98:J101) | K23: =_xlfn.XLOOKUP($C$4,$D$98:$D$101,K98:K101) | L23: Derived-DB | M23: Medium
A24: D17 | B24: Maintenance capex | C24: % of revenue | D24: 0.03 | E24: =_xlfn.XLOOKUP($C$4,$D$102:$D$105,E102:E105) | F24: =_xlfn.XLOOKUP($C$4,$D$102:$D$105,F102:F105) | G24: =_xlfn.XLOOKUP($C$4,$D$102:$D$105,G102:G105) | H24: =_xlfn.XLOOKUP($C$4,$D$102:$D$105,H102:H105) | I24: =_xlfn.XLOOKUP($C$4,$D$102:$D$105,I102:I105) | J24: =_xlfn.XLOOKUP($C$4,$D$102:$D$105,J102:J105) | K24: =_xlfn.XLOOKUP($C$4,$D$102:$D$105,K102:K105) | L24: Indicative | M24: Low
A25: D18 | B25: Net working capital | C25: days of revenue | D25: 45 | E25: =_xlfn.XLOOKUP($C$4,$D$106:$D$109,E106:E109) | F25: =_xlfn.XLOOKUP($C$4,$D$106:$D$109,F106:F109) | G25: =_xlfn.XLOOKUP($C$4,$D$106:$D$109,G106:G109) | H25: =_xlfn.XLOOKUP($C$4,$D$106:$D$109,H106:H109) | I25: =_xlfn.XLOOKUP($C$4,$D$106:$D$109,I106:I109) | J25: =_xlfn.XLOOKUP($C$4,$D$106:$D$109,J106:J109) | K25: =_xlfn.XLOOKUP($C$4,$D$106:$D$109,K106:K109) | L25: Not sourced | M25: Low
A26: D19 | B26: Exit EV/EBITDA multiple | C26: x | E26: =_xlfn.XLOOKUP($C$4,$D$110:$D$113,E110:E113) | F26: =_xlfn.XLOOKUP($C$4,$D$110:$D$113,F110:F113) | G26: =_xlfn.XLOOKUP($C$4,$D$110:$D$113,G110:G113) | H26: =_xlfn.XLOOKUP($C$4,$D$110:$D$113,H110:H113) | I26: =_xlfn.XLOOKUP($C$4,$D$110:$D$113,I110:I113) | J26: =_xlfn.XLOOKUP($C$4,$D$110:$D$113,J110:J113) | K26: =_xlfn.XLOOKUP($C$4,$D$110:$D$113,K110:K113) | L26: Not sourced | M26: Low
A27: D20 | B27: WACC (nominal, INR) | C27: % | D27: =$D$168 | E27: =_xlfn.XLOOKUP($C$4,$D$114:$D$117,E114:E117) | F27: =_xlfn.XLOOKUP($C$4,$D$114:$D$117,F114:F117) | G27: =_xlfn.XLOOKUP($C$4,$D$114:$D$117,G114:G117) | H27: =_xlfn.XLOOKUP($C$4,$D$114:$D$117,H114:H117) | I27: =_xlfn.XLOOKUP($C$4,$D$114:$D$117,I114:I117) | J27: =_xlfn.XLOOKUP($C$4,$D$114:$D$117,J114:J117) | K27: =_xlfn.XLOOKUP($C$4,$D$114:$D$117,K114:K117) | L27: Composite | M27: Medium
A28: D21 | B28: Finished steel imports | C28: Mt | D28: ='[1]Imports & Exports'!$H$6 | E28: =_xlfn.XLOOKUP($C$4,$D$118:$D$121,E118:E121) | F28: =_xlfn.XLOOKUP($C$4,$D$118:$D$121,F118:F121) | G28: =_xlfn.XLOOKUP($C$4,$D$118:$D$121,G118:G121) | H28: =_xlfn.XLOOKUP($C$4,$D$118:$D$121,H118:H121) | I28: =_xlfn.XLOOKUP($C$4,$D$118:$D$121,I118:I121) | J28: =_xlfn.XLOOKUP($C$4,$D$118:$D$121,J118:J121) | K28: =_xlfn.XLOOKUP($C$4,$D$118:$D$121,K118:K121) | L28: Derived-DB | M28: Medium
A29: D22 | B29: Secondary and unattributed capacity additions | C29: Mtpa p.a. | D29: ='[1]Production Capacity'!$H$7 | E29: =_xlfn.XLOOKUP($C$4,$D$122:$D$125,E122:E125) | F29: =_xlfn.XLOOKUP($C$4,$D$122:$D$125,F122:F125) | G29: =_xlfn.XLOOKUP($C$4,$D$122:$D$125,G122:G125) | H29: =_xlfn.XLOOKUP($C$4,$D$122:$D$125,H122:H125) | I29: =_xlfn.XLOOKUP($C$4,$D$122:$D$125,I122:I125) | J29: =_xlfn.XLOOKUP($C$4,$D$122:$D$125,J122:J125) | K29: =_xlfn.XLOOKUP($C$4,$D$122:$D$125,K122:K125) | L29: Derived-DB | M29: Medium
A30: D23 | B30: Price sensitivity to capacity utilisation (lagged) | C30: x | D30: 0.4 | E30: =_xlfn.XLOOKUP($C$4,$D$126:$D$129,E126:E129) | F30: =_xlfn.XLOOKUP($C$4,$D$126:$D$129,F126:F129) | G30: =_xlfn.XLOOKUP($C$4,$D$126:$D$129,G126:G129) | H30: =_xlfn.XLOOKUP($C$4,$D$126:$D$129,H126:H129) | I30: =_xlfn.XLOOKUP($C$4,$D$126:$D$129,I126:I129) | J30: =_xlfn.XLOOKUP($C$4,$D$126:$D$129,J126:J129) | K30: =_xlfn.XLOOKUP($C$4,$D$126:$D$129,K126:K129) | L30: Indicative | M30: Low
A31: D24 | B31: Normal capacity utilisation | C31: % | D31: 0.8 | E31: =_xlfn.XLOOKUP($C$4,$D$130:$D$133,E130:E133) | F31: =_xlfn.XLOOKUP($C$4,$D$130:$D$133,F130:F133) | G31: =_xlfn.XLOOKUP($C$4,$D$130:$D$133,G130:G133) | H31: =_xlfn.XLOOKUP($C$4,$D$130:$D$133,H130:H133) | I31: =_xlfn.XLOOKUP($C$4,$D$130:$D$133,I130:I133) | J31: =_xlfn.XLOOKUP($C$4,$D$130:$D$133,J130:J133) | K31: =_xlfn.XLOOKUP($C$4,$D$130:$D$133,K130:K133) | L31: Derived-DB | M31: Medium
A32: D25 | B32: Maximum practical capacity utilisation | C32: % | D32: 0.92 | E32: =_xlfn.XLOOKUP($C$4,$D$134:$D$137,E134:E137) | F32: =_xlfn.XLOOKUP($C$4,$D$134:$D$137,F134:F137) | G32: =_xlfn.XLOOKUP($C$4,$D$134:$D$137,G134:G137) | H32: =_xlfn.XLOOKUP($C$4,$D$134:$D$137,H134:H137) | I32: =_xlfn.XLOOKUP($C$4,$D$134:$D$137,I134:I137) | J32: =_xlfn.XLOOKUP($C$4,$D$134:$D$137,J134:J137) | K32: =_xlfn.XLOOKUP($C$4,$D$134:$D$137,K134:K137) | L32: Indicative | M32: Low
A33: D26 | B33: Depreciation and amortisation | C33: % of revenue | D33: ='Cash Flow Model'!$C$92 | E33: =_xlfn.XLOOKUP($C$4,$D$138:$D$141,E138:E141) | F33: =_xlfn.XLOOKUP($C$4,$D$138:$D$141,F138:F141) | G33: =_xlfn.XLOOKUP($C$4,$D$138:$D$141,G138:G141) | H33: =_xlfn.XLOOKUP($C$4,$D$138:$D$141,H138:H141) | I33: =_xlfn.XLOOKUP($C$4,$D$138:$D$141,I138:I141) | J33: =_xlfn.XLOOKUP($C$4,$D$138:$D$141,J138:J141) | K33: =_xlfn.XLOOKUP($C$4,$D$138:$D$141,K138:K141) | L33: Derived-DB | M33: High
A36: SCENARIO DRIVER MATRIX
A37: Sl No | B37: Driver | C37: Unit | D37: Scenario | E37: FY2027E | F37: FY2028E | G37: FY2029E | H37: FY2030E | I37: FY2031E | J37: FY2032E | K37: FY2033E | L37: Source | M37: Audit Code
A38: 1 | B38: India real GDP growth | C38: % | D38: Base Case | E38: 0.066 | F38: 0.068 | G38: 0.068 | H38: 0.067 | I38: 0.067 | J38: 0.065 | K38: 0.065 | L38: RBI-Jun26 | M38: MA01
D39: Bull Case | E39: 0.074 | F39: 0.076 | G39: 0.075 | H39: 0.074 | I39: 0.073 | J39: 0.072 | K39: 0.07
D40: Bear Case | E40: 0.056 | F40: 0.058 | G40: 0.06 | H40: 0.061 | I40: 0.062 | J40: 0.062 | K40: 0.062
D41: Stress Case | E41: 0.044 | F41: 0.048 | G41: 0.055 | H41: 0.058 | I41: 0.06 | J41: 0.06 | K41: 0.06
A42: 2 | B42: Steel demand elasticity to real GDP | C42: x | D42: Base Case | E42: 1.15 | F42: 1.15 | G42: 1.12 | H42: 1.1 | I42: 1.08 | J42: 1.06 | K42: 1.05 | L42: Derived-DB | M42: MA02
D43: Bull Case | E43: 1.3 | F43: 1.28 | G43: 1.25 | H43: 1.22 | I43: 1.2 | J43: 1.18 | K43: 1.15
D44: Bear Case | E44: 1 | F44: 1 | G44: 0.98 | H44: 0.97 | I44: 0.96 | J44: 0.95 | K44: 0.95
...

Sheet Model Calibration
A1: MODEL CALIBRATION
A2: Industry Financial Model | Indian Steel Industry | Horizon FY2027E-FY2033E | Base year FY2026A
L3: Active Scenario | N3: ='Control Panel'!$E$17
A4: Purpose
A5: This sheet extracts the key industry benchmark values from the Master Industry Database and converts them into modelling variables used throughout the workbook.
A8: Industry Size Calibration
A9: ID | B9: Variable | C9: Unit | D9: FY2026A | E9: Source | F9: Model Used In | G9: Status
A10: MC001 | B10: Crude Steel Production | C10: Mt | D10: ='[1]Production Volume'!$H$6 | E10: Database | F10: Demand Model | G10: ✅
A11: MC002 | B11: Finished Steel Production | C11: Mt | D11: ='[1]Production Volume'!$H$7 | E11: Database | F11: Supply Model | G11: ✅
A12: MC003 | B12: Finished Steel Consumption | C12: Mt | D12: ='[1]Demand & Consumption'!$H$6 | E12: Database | F12: Demand Model | G12: ✅
A13: MC004 | B13: Installed Capacity | C13: MTPA | D13: ='[1]Production Capacity'!$H$6 | E13: Database | F13: Capacity Model | G13: ✅
A14: MC005 | B14: Capacity Utilisation | C14: % | D14: =D10/D13 | E14: Derived | F14: Capacity Model | G14: ✅
A17: Industry Economics
A18: ID | B18: Variable | C18: Unit | D18: FY2026A | E18: Source | F18: Model Used In
A19: MC101 | B19: Average Steel Realisation | C19: ₹/t | D19: ='[1]Steel Prices'!$H$12 | E19: Database | F19: Revenue Model
A20: MC102 | B20: EBITDA per Ton | C20: ₹/t | D20: ='[1]Revenue & EBITDA'!$H$43 | E20: Database | F20: EBITDA Model
A21: MC103 | B21: Cash Cost per Ton | C21: ₹/t | D21: =D23-D20 | E21: Derived | F21: Cost Curve
A22: MC104 | B22: EBITDA Margin | C22: % | D22: ='[1]Revenue & EBITDA'!$H$33 | E22: Database | F22: Margin Model
A23: MC105 | B23: Revenue per Ton | C23: ₹/t | D23: ='Revenue Forecast'!$C$95/'Revenue Forecast'!$C$93*10 | E23: Derived | F23: Revenue Model
A26: Commodity Benchmarks
A27: ID | B27: Variable | C27: Unit | D27: FY2026A | E27: Source | F27: Model Used In
A28: MC201 | B28: Iron Ore (62% Fe CFR China) | C28: US$/dmt | D28: ='[1]Raw Materials'!$H$6 | E28: Database | F28: Raw Material Model
A29: MC202 | B29: Premium HCC Coal | C29: US$/t | D29: ='[1]Raw Materials'!$H$11 | E29: Database | F29: Raw Material Model
A30: MC203 | B30: Thermal Coal | C30: US$/t | D30: ='[1]Raw Materials'!$H$13 | E30: Database | F30: Cost Model
A31: MC204 | B31: Domestic HRC Price | C31: ₹/t | D31: ='[1]Steel Prices'!$H$6 | E31: Database | F31: Steel Price Model
A34: Trade Benchmarks
A35: ID | B35: Variable | C35: Unit | D35: FY2026A | E35: Source | F35: Model Used In
A36: MC301 | B36: Imports | C36: Mt | D36: ='[1]Imports & Exports'!$H$6 | E36: Database | F36: Trade Model
A37: MC302 | B37: Exports | C37: Mt | D37: ='[1]Imports & Exports'!$H$7 | E37: Database | F37: Trade Model
A38: MC303 | B38: Stock Change | C38: Mt | D38: ='[1]Demand & Consumption'!$H$9 | E38: Database | F38: Trade Model
A41: Industry Ratios
A42: ID | B42: Variable | C42: FY2026A | D42: Formula | E42: Model Used In
A43: MC401 | B43: Crude to Finished Ratio | C43: =D10/D12 | D43: Derived | E43: Demand
A44: MC402 | B44: Per Capita Consumption | C44: ='[1]Demand & Consumption'!$H$8 | D44: Database | E44: Demand
A45: MC403 | B45: Industry Volume Coverage | C45: =SUM('[1]Production Volume'!$H$15:$H$19)/'[1]Production Volume'!$H$21 | D45: Derived | E45: Calibration
A46: MC404 | B46: Capacity Utilisation | C46: =D10/D13 | D46: Derived | E46: Capacity
A47: MC405 | B47: Import Dependency | C47: =D36/D12 | D47: Derived | E47: Trade
A50: Calibration Checks
A51: ID | B51: Check | C51: Formula | E51: Result
A52: MC501 | B52: Production | C52: Capacity × Utilisation | E52: =IF(ABS($D$13*$D$14-$D$10)<0.05,"PASS","FAIL")
...

Sheet Macroeconomic Model
A1: MACROECONOMIC MODEL
A2: Industry Financial Model | Indian Steel Industry | Horizon FY2027E-FY2033E | Base year FY2026A
N3: Active Scenario | P3: ='Control Panel'!$E$17
A4: OBJECTIVE
A5: Convert macroeconomic assumptions into economic drivers for the steel industry.
A6: METHODOLOGY
A7: Real GDP growth and CPI are taken from RBI's June-2026 Monetary Policy Committee projections for FY2027 and converge to a steady state thereafter, because no Indian official body publishes a real GDP path beyond roughly five years. USD/INR is anchored on the 22-Jun-2026 spot of 94. Index rows compound the growth rates so that cumulative effects are visible rather than implied.
A8: UNITS
A9: Percentages as decimals. Indices FY2026A = ~100 (USD/INR) in rupees per dollar.
A11: Executive Summary
A12: Metric | B12: FY2026A | C12: FY2027E | D12: FY2028E | E12: FY2029E | F12: FY2030E | G12: FY2031E | H12: FY2032E | I12: FY2033E | J12: Audit Code
A13: GDP Growth (%) | B13: ='Model Assumptions'!D8 | C13: ='Model Assumptions'!E8 | D13: ='Model Assumptions'!F8 | E13: ='Model Assumptions'!G8 | F13: ='Model Assumptions'!H8 | G13: ='Model Assumptions'!I8 | H13: ='Model Assumptions'!J8 | I13: ='Model Assumptions'!K8 | J13: MM01
A14: CPI Inflation (%) | B14: ='Model Assumptions'!D11 | C14: ='Model Assumptions'!E11 | D14: ='Model Assumptions'!F11 | E14: ='Model Assumptions'!G11 | F14: ='Model Assumptions'!H11 | G14: ='Model Assumptions'!I11 | H14: ='Model Assumptions'!J11 | I14: ='Model Assumptions'!K11 | J14: MM02
A15: Repo Rate (%) | B15: 0.0525 | C15: 0.0525 | D15: 0.0525 | E15: 0.0525 | F15: 0.0525 | G15: 0.0525 | H15: 0.0525 | I15: 0.0525 | J15: MM03
A16: Real GDP Index | B16: 100 | C16: =B16*(1+C13) | D16: =C16*(1+D13) | E16: =D16*(1+E13) | F16: =E16*(1+F13) | G16: =F16*(1+G13) | H16: =G16*(1+H13) | I16: =H16*(1+I13) | J16: MM04
A17: Nominal GDP Index | B17: 100 | C17: =B17*(1+C13)*(1+C14) | D17: =C17*(1+D13)*(1+D14) | E17: =D17*(1+E13)*(1+E14) | F17: =E17*(1+F13)*(1+F14) | G17: =F17*(1+G13)*(1+G14) | H17: =G17*(1+H13)*(1+H14) | I17: =H17*(1+I13)*(1+I14) | J17: MM05
A18: USD/INR | B18: ='Model Assumptions'!D10 | C18: ='Model Assumptions'!E10 | D18: ='Model Assumptions'!F10 | E18: ='Model Assumptions'!G10 | F18: ='Model Assumptions'!H10 | G18: ='Model Assumptions'!I10 | H18: ='Model Assumptions'!J10 | I18: ='Model Assumptions'!K10 | J18: MM06
A19: INR Depreciation | C19: =C18/B18-1 | D19: =D18/C18-1 | E19: =E18/D18-1 | F19: =F18/E18-1 | G19: =G18/F18-1 | H19: =H18/G18-1 | I19: =I18/H18-1 | J19: MM07
A20: Brent Oil (US$/bbl) | B20: 79 | C20: 79 | D20: 79 | E20: 79 | F20: 79 | G20: 79 | H20: 79 | I20: 79 | J20: MM08
A21: 10 Year G Sec Yield | B21: 0.068 | C21: 0.068 | D21: 0.068 | E21: 0.068 | F21: 0.068 | G21: 0.068 | H21: 0.068 | I21: 0.068 | J21: MM09
A22: WACC (Nominal) | B22: ='Model Assumptions'!D27 | C22: ='Model Assumptions'!E27 | D22: ='Model Assumptions'!F27 | E22: ='Model Assumptions'!G27 | F22: ='Model Assumptions'!H27 | G22: ='Model Assumptions'!I27 | H22: ='Model Assumptions'!J27 | I22: ='Model Assumptions'!K27 | J22: MM10
A25: Leading Indicators
A26: Indicator | B26: FY2025A | C26: FY2026A | D26: Trend | E26: Impact
A27: PMI Manufacturing | D27: =IF(C27>B27,"▲",IF(C27<B27,"▼","►"))
A28: Core Sector Growth | D28: =IF(C28>B28,"▲",IF(C28<B28,"▼","►"))
A29: Infrastructure Spending | D29: =IF(C29>B29,"▲",IF(C29<B29,"▼","►"))
A30: Government Capex | D30: =IF(C30>B30,"▲",IF(C30<B30,"▼","►"))
A31: Housing Completions | D31: =IF(C31>B31,"▲",IF(C31<B31,"▼","►"))
A32: Vehicle Production | D32: =IF(C32>B32,"▲",IF(C32<B32,"▼","►"))
A33: Railway Capex | D33: =IF(C33>B33,"▲",IF(C33<B33,"▼","►"))
A36: Commodity Environment
A37: Commodity | B37: FY2026A | C37: FY2033E | D37: Trend | E37: Audit Code
A38: Brent Oil | B38: =$B$20 | C38: =$I$20 | D38: =IF(C38>B38,"▲ Increase",IF(C38<B38,"▼ Decrease","► Stable")) | E38: MM11
A39: Iron Ore | B39: ='Raw Material Forecast'!$C$61 | C39: ='Raw Material Forecast'!$J$61 | D39: =IF(C39>B39,"▲ Increase",IF(C39<B39,"▼ Decrease","► Stable")) | E39: MM12
A40: HCC Coal | B40: ='Raw Material Forecast'!$C$62 | C40: ='Raw Material Forecast'!$J$62 | D40: =IF(C40>B40,"▲ Increase",IF(C40<B40,"▼ Decrease","► Stable")) | E40: MM13
A41: Thermal Coal | B41: 111.5 | D41: =IF(C41>B41,"▲ Increase",IF(C41<B41,"▼ Decrease","► Stable")) | E41: MM14
A44: Macro Outlook
A45: GROWTH. The RBI cut its FY2027 real GDP projection to 6.6% from 6.9% at the 05-Jun-2026 MPC, citing the West Asia conflict, energy prices and monsoon risk, against an estimated 7.6% for FY2026 and a Q4FY2026 actual of 7.7%. The base case adopts 6.6% unchanged and converges to a 6.5% steady state; it does not extrapolate the FY2026 outturn, which was flattered by a low base and front-loaded government capex.
A46: PRICES AND POLICY. CPI is projected at 5.1% for FY2027, 50bps above the previous projection, converging to the 4.5% mid-point of the RBI target band. The repo rate was held at 5.25% and the 10-year G-sec was 6.833% on 31-Jul-2026. Conversion cost inflation in the model is anchored on this CPI path rather than on a separately asserted wage or power series.
A47: CURRENCY. USD/INR averaged 88.4 in FY2026 and was 94 spot on 22-Jun-2026 within an 85 to 98 52-week range. The base case takes the rupee to 100.5 by FY2033E. This is the second largest single driver of industry EBITDA in the model, because iron ore and coking coal are priced in dollars while realisation is in rupees.
...

Sheet Steel Demand Model
A1: STEEL DEMAND MODEL
A2: Industry Financial Model | Indian Steel Industry | Horizon FY2027E-FY2033E | Base year FY2026A
M3: Active Scenario | O3: ='Control Panel'!$E$17
A4: OBJECTIVE
A5: Forecasts India's apparent finished steel consumption, the demand anchor for the whole model.
A7: Executive Summary
A8: Metric | B8: FY26A | C8: FY27E | D8: FY28E | E8: FY29E | F8: FY30E | G8: FY31E | H8: FY32E | I8: FY33E | J8: Audit Code
A9: Apparent Steel Consumption (Mt) | B9: =$C$75 | C9: =$D$75 | D9: =$E$75 | E9: =$F$75 | F9: =$G$75 | G9: =$H$75 | H9: =$I$75 | I9: =$J$75 | J9: SD01
A10: Demand Growth (%) | B10: =$C$74 | C10: =$D$74 | D10: =$E$74 | E10: =$F$74 | F10: =$G$74 | G10: =$H$74 | H10: =$I$74 | I10: =$J$74 | J10: SD02
A11: Per Capita Consumption (kg) | B11: =$C$80 | C11: =$D$80 | D11: =$E$80 | E11: =$F$80 | F11: =$G$80 | G11: =$H$80 | H11: =$I$80 | I11: =$J$80 | J11: SD03
A12: Domestic Demand Share (%) | B12: =IFERROR(C75/(C75+'Trade Model'!C72),"") | C12: =IFERROR(D75/(D75+'Trade Model'!D72),"") | D12: =IFERROR(E75/(E75+'Trade Model'!E72),"") | E12: =IFERROR(F75/(F75+'Trade Model'!F72),"") | F12: =IFERROR(G75/(G75+'Trade Model'!G72),"") | G12: =IFERROR(H75/(H75+'Trade Model'!H72),"") | H12: =IFERROR(I75/(I75+'Trade Model'!I72),"") | I12: =IFERROR(J75/(J75+'Trade Model'!J72),"") | J12: SD04
A13: CAGR (FY26–FY33) | C13: =(C9-B9)/B9 | D13: =(D9-C9)/C9 | E13: =(E9-D9)/D9 | F13: =(F9-E9)/E9 | G13: =(G9-F9)/F9 | H13: =(H9-G9)/G9 | I13: =(I9-H9)/H9 | J13: SD05
A16: Historical Demand
A17: Year | B17: Consumption (Mt) | C17: Growth % | D17: Source | F17: Audit Code
A18: FY21 | B18: ='[1]Demand & Consumption'!$C$6 | C18: -0.0527 | D18: JPC / Ministry of Steel | F18: SD06
A19: FY22 | B19: ='[1]Demand & Consumption'!$D$6 | C19: =(B19-B18)/B18 | D19: JPC / Ministry of Steel | F19: SD07
A20: FY23 | B20: ='[1]Demand & Consumption'!$E$6 | C20: =(B20-B19)/B19 | D20: JPC / Ministry of Steel | F20: SD08
A21: FY24 | B21: ='[1]Demand & Consumption'!$F$6 | C21: =(B21-B20)/B20 | D21: JPC / Ministry of Steel | F21: SD09
A22: FY25 | B22: ='[1]Demand & Consumption'!$G$6 | C22: =(B22-B21)/B21 | D22: JPC / Ministry of Steel | F22: SD10
A23: FY26 | B23: ='[1]Demand & Consumption'!$H$6 | C23: =(B23-B22)/B22 | D23: JPC / Ministry of Steel | F23: SD11
A26: Per Capita Analysis
A27: Year | B27: Population (Mn) | C27: Steel Consumption (Mt) | D27: Per Capita (kg) | E27: Audit Code
A28: FY26 | B28: =$C$78*1000 | C28: =$C$75 | D28: =IFERROR(C28/B28*1000,"") | E28: SD12
A29: FY27 | B29: =$D$78*1000 | C29: =$D$75 | D29: =IFERROR(C29/B29*1000,"") | E29: SD13
A30: FY28 | B30: =$E$78*1000 | C30: =$E$75 | D30: =IFERROR(C30/B30*1000,"") | E30: SD14
A31: FY29 | B31: =$F$78*1000 | C31: =$F$75 | D31: =IFERROR(C31/B31*1000,"") | E31: SD15
A32: FY30 | B32: =$G$78*1000 | C32: =$G$75 | D32: =IFERROR(C32/B32*1000,"") | E32: SD16
A33: FY31 | B33: =$H$78*1000 | C33: =$H$75 | D33: =IFERROR(C33/B33*1000,"") | E33: SD17
A34: FY32 | B34: =$I$78*1000 | C34: =$I$75 | D34: =IFERROR(C34/B34*1000,"") | E34: SD18
A35: FY33 | B35: =$J$78*1000 | C35: =$J$75 | D35: =IFERROR(C35/B35*1000,"") | E35: SD19
A38: International Comparision
A39: Country | B39: Per Capita Steel Consumption (kg) | E39: Audit Code
A40: India | B40: =C80 | E40: SD20
A41: China | B41: 604 | E41: SD21
A42: Japan | E42: SD22
A43: South Korea | E43: SD23
A44: USA | E44: SD24
A45: Global Average | B45: 215 | E45: SD25
A48: Demand Forecast
A49: Year | B49: Base Demand | C49: Macro Adjustment | D49: Sector Adjustment | E49: Final Demand | F49: Audit Code
...

Sheet Steel Supply Model
A1: STEEL SUPLY MODEL
A2: Industry Financial Model | Indian Steel Industry | Horizon FY2027E-FY2033E | Base year FY2026A
N3: Active Scenario | P3: ='Control Panel'!$E$17
A4: OBJECTIVE
A5: Forecast India's finished steel supply and reconcile it with domestic demand, capacity, imports, exports, and inventory changes.
A7: Executive Summary
A8: KPI | B8: FY26A | C8: FY27E | D8: FY28E | E8: FY29E | F8: FY30E | G8: FY31E | H8: FY32E | I8: FY33E
A9: Crude Steel Production (Mt) | B9: =$C$88 | C9: =$D$88 | D9: =$E$88 | E9: =$F$88 | F9: =$G$88 | G9: =$H$88 | H9: =$I$88 | I9: =$J$88
A10: Finished Steel Production (Mt) | B10: =$C$90 | C10: =$D$90 | D10: =$E$90 | E10: =$F$90 | F10: =$G$90 | G10: =$H$90 | H10: =$I$90 | I10: =$J$90
A11: Installed Capacity (MTPA) | B11: ='Capacity Forecast'!C$96 | C11: ='Capacity Forecast'!D$96 | D11: ='Capacity Forecast'!E$96 | E11: ='Capacity Forecast'!F$96 | F11: ='Capacity Forecast'!G$96 | G11: ='Capacity Forecast'!H$96 | H11: ='Capacity Forecast'!I$96 | I11: ='Capacity Forecast'!J$96
A12: Capacity Utilisation (%) | B12: ='Capacity Utilisation'!C$65 | C12: ='Capacity Utilisation'!D$65 | D12: ='Capacity Utilisation'!E$65 | E12: ='Capacity Utilisation'!F$65 | F12: ='Capacity Utilisation'!G$65 | G12: ='Capacity Utilisation'!H$65 | H12: ='Capacity Utilisation'!I$65 | I12: ='Capacity Utilisation'!J$65
A13: Domestic Supply (Mt) | B13: =C90+'Trade Model'!C70-'Trade Model'!C72 | C13: =D90+'Trade Model'!D70-'Trade Model'!D72 | D13: =E90+'Trade Model'!E70-'Trade Model'!E72 | E13: =F90+'Trade Model'!F70-'Trade Model'!F72 | F13: =G90+'Trade Model'!G70-'Trade Model'!G72 | G13: =H90+'Trade Model'!H70-'Trade Model'!H72 | H13: =I90+'Trade Model'!I70-'Trade Model'!I72 | I13: =J90+'Trade Model'!J70-'Trade Model'!J72
A14: Import Dependency (%) | B14: ='Trade Model'!C$77 | C14: ='Trade Model'!D$77 | D14: ='Trade Model'!E$77 | E14: ='Trade Model'!F$77 | F14: ='Trade Model'!G$77 | G14: ='Trade Model'!H$77 | H14: ='Trade Model'!I$77 | I14: ='Trade Model'!J$77
A15: Export Share (%) | B15: ='Trade Model'!C$78 | C15: ='Trade Model'!D$78 | D15: ='Trade Model'!E$78 | E15: ='Trade Model'!F$78 | F15: ='Trade Model'!G$78 | G15: ='Trade Model'!H$78 | H15: ='Trade Model'!I$78 | I15: ='Trade Model'!J$78
A16: Supply Surplus / Deficit (Mt) | B16: =B13-'Steel Demand Model'!B9 | C16: =C13-'Steel Demand Model'!C9 | D16: =D13-'Steel Demand Model'!D9 | E16: =E13-'Steel Demand Model'!E9 | F16: =F13-'Steel Demand Model'!F9 | G16: =G13-'Steel Demand Model'!G9 | H16: =H13-'Steel Demand Model'!H9 | I16: =I13-'Steel Demand Model'!I9
A19: Historical Supply
A20: Year | B20: Crude Production | C20: Finished Production | D20: Growth %
A21: FY21 | B21: ='[1]Production Volume'!$C$6 | C21: ='[1]Production Volume'!$C$7
A22: FY22 | B22: ='[1]Demand & Consumption'!$D$6 | C22: ='[1]Production Volume'!$D$7 | D22: =(C22-C21)/C21
A23: FY23 | B23: ='[1]Demand & Consumption'!$E$6 | C23: ='[1]Production Volume'!$E$7 | D23: =(C23-C22)/C22
A24: FY24 | B24: ='[1]Demand & Consumption'!$F$6 | C24: ='[1]Production Volume'!$F$7 | D24: =(C24-C23)/C23
A25: FY25 | B25: ='[1]Demand & Consumption'!$G$6 | C25: ='[1]Production Volume'!$G$7 | D25: =(C25-C24)/C24
A26: FY26 | B26: ='[1]Demand & Consumption'!$H$6 | C26: ='[1]Production Volume'!$H$7 | D26: =(C26-C25)/C25
A29: Supply Build Up
A30: Item | B30: FY26A | C30: FY27E | D30: FY28E | E30: FY29E | F30: FY30E | G30: FY31E | H30: FY32E | I30: FY33E | J30: Audit Code
A31: Opening Production | B31: ='[1]Production Capacity'!$G$8 | C31: =B35 | D31: =C35 | E31: =D35 | F31: =E35 | G31: =F35 | H31: =G35 | I31: =H35
A32: Capacity Addition | B32: ='Capacity Forecast'!C$95 | C32: ='Capacity Forecast'!D$95 | D32: ='Capacity Forecast'!E$95 | E32: ='Capacity Forecast'!F$95 | F32: ='Capacity Forecast'!G$95 | G32: ='Capacity Forecast'!H$95 | H32: ='Capacity Forecast'!I$95 | I32: ='Capacity Forecast'!J$95
A33: Effective Capacity | B33: ='Capacity Forecast'!C$96 | C33: ='Capacity Forecast'!D$96 | D33: ='Capacity Forecast'!E$96 | E33: ='Capacity Forecast'!F$96 | F33: ='Capacity Forecast'!G$96 | G33: ='Capacity Forecast'!H$96 | H33: ='Capacity Forecast'!I$96 | I33: ='Capacity Forecast'!J$96
A34: Capacity Utilisation | B34: ='Capacity Utilisation'!C$65 | C34: ='Capacity Utilisation'!D$65 | D34: ='Capacity Utilisation'!E$65 | E34: ='Capacity Utilisation'!F$65 | F34: ='Capacity Utilisation'!G$65 | G34: ='Capacity Utilisation'!H$65 | H34: ='Capacity Utilisation'!I$65 | I34: ='Capacity Utilisation'!J$65
A35: Crude Steel Production | B35: =C$88 | C35: =D$88 | D35: =E$88 | E35: =F$88 | F35: =G$88 | G35: =H$88 | H35: =I$88 | I35: =J$88
A36: Crude-to-Finished Ratio | B36: =C$82 | C36: =D$82 | D36: =E$82 | E36: =F$82 | F36: =G$82 | G36: =H$82 | H36: =I$82 | I36: =J$82
A37: Finished Steel Production | B37: =C$90 | C37: =D$90 | D37: =E$90 | E37: =F$90 | F37: =G$90 | G37: =H$90 | H37: =I$90 | I37: =J$90
A38: Imports | B38: ='Trade Model'!C$70 | C38: ='Trade Model'!D$70 | D38: ='Trade Model'!E$70 | E38: ='Trade Model'!F$70 | F38: ='Trade Model'!G$70 | G38: ='Trade Model'!H$70 | H38: ='Trade Model'!I$70 | I38: ='Trade Model'!J$70
A39: Exports | B39: ='Trade Model'!C$72 | C39: ='Trade Model'!D$72 | D39: ='Trade Model'!E$72 | E39: ='Trade Model'!F$72 | F39: ='Trade Model'!G$72 | G39: ='Trade Model'!H$72 | H39: ='Trade Model'!I$72 | I39: ='Trade Model'!J$72
A40: Inventory Adjustment | B40: =C$80 | C40: =D$80 | D40: =E$80 | E40: =F$80 | F40: =G$80 | G40: =H$80 | H40: =I$80 | I40: =J$80
A41: Domestic Supply Available | B41: =B37+B38-B39 | C41: =C37+C38-C39 | D41: =D37+D38-D39 | E41: =E37+E38-E39 | F41: =F37+F38-F39 | G41: =G37+G38-G39 | H41: =H37+H38-H39 | I41: =I37+I38-I39 | J41: SS01
A44: Supply Demand Reconcilation
A45: Item | B45: FY26A | C45: FY27E | D45: FY28E | E45: FY29E | F45: FY30E | G45: FY31E | H45: FY32E | I45: FY33E
A46: Domestic Supply | B46: =B37 | C46: =C37 | D46: =D37 | E46: =E37 | F46: =F37 | G46: =G37 | H46: =H37 | I46: =I37
A47: Imports | B47: =B38 | C47: =C38 | D47: =D38 | E47: =E38 | F47: =F38 | G47: =G38 | H47: =H38 | I47: =I38
...

Sheet Capacity Forecast
A1: CAPACITY FORECAST
A2: Industry Financial Model | Indian Steel Industry | Horizon FY2027E-FY2033E | Base year FY2026A
J3: Active Scenario | L3: ='Control Panel'!$E$17
A4: OBJECTIVE
A5: Forecast installed steelmaking capacity by incorporating brownfield expansions, greenfield projects, closures, and debottlenecking.
A7: Executive Summary
A8: KPI | B8: FY26A | C8: FY27E | D8: FY28E | E8: FY29E | F8: FY30E | G8: FY31E | H8: FY32E | I8: FY33E
A9: Installed Capacity (Mtpa) | B9: =C$96 | C9: =D$96 | D9: =E$96 | E9: =F$96 | F9: =G$96 | G9: =H$96 | H9: =I$96 | I9: =J$96
A10: Capacity Addition (Mt) | B10: =C$95 | C10: =D$95 | D10: =E$95 | E10: =F$95 | F10: =G$95 | G10: =H$95 | H10: =I$95 | I10: =J$95
A11: Capacity Growth (%) | B11: =B10/B9 | C11: =C10/C9 | D11: =D10/D9 | E11: =E10/E9 | F11: =F10/F9 | G11: =G10/G9 | H11: =H10/H9 | I11: =I10/I9
A12: Capacity Utilisation (%) | B12: ='Capacity Utilisation'!C$65 | C12: ='Capacity Utilisation'!D$65 | D12: ='Capacity Utilisation'!E$65 | E12: ='Capacity Utilisation'!F$65 | F12: ='Capacity Utilisation'!G$65 | G12: ='Capacity Utilisation'!H$65 | H12: ='Capacity Utilisation'!I$65 | I12: ='Capacity Utilisation'!J$65
A13: Spare Capacity (Mt) | B13: =C96-'Steel Supply Model'!C88 | C13: =D96-'Steel Supply Model'!D88 | D13: =E96-'Steel Supply Model'!E88 | E13: =F96-'Steel Supply Model'!F88 | F13: =G96-'Steel Supply Model'!G88 | G13: =H96-'Steel Supply Model'!H88 | H13: =I96-'Steel Supply Model'!I88 | I13: =J96-'Steel Supply Model'!J88
A14: Capacity Gap (Mt) | B14: =C96-'Steel Supply Model'!C83 | C14: =D96-'Steel Supply Model'!D83 | D14: =E96-'Steel Supply Model'!E83 | E14: =F96-'Steel Supply Model'!F83 | F14: =G96-'Steel Supply Model'!G83 | G14: =H96-'Steel Supply Model'!H83 | H14: =I96-'Steel Supply Model'!I83 | I14: =J96-'Steel Supply Model'!J83
A17: Company-wise Capacity
A18: Company | B18: FY26A | C18: FY27E | D18: FY28E | E18: FY29E | F18: FY30E | G18: FY31E | H18: FY32E | I18: FY33E
A19: Tata Steel | B19: ='[1]Production Capacity'!$H$13 | C19: =B19 | D19: =C19 | E19: =D19 | F19: =E19+F30 | G19: =F19 | H19: =G19 | I19: =H19+F31
A20: JSW Steel | B20: ='[1]Production Capacity'!$H$14 | C20: =B20+F32 | D20: =C20 | E20: =D20 | F20: =E20+F33 | G20: =F20+F34 | H20: =G20 | I20: =H20
A21: SAIL | B21: ='[1]Production Capacity'!$H$15 | C21: =B21 | D21: =C21 | E21: =D21+F37 | F21: =E21+F36 | G21: =F21+F35 | H21: =G21 | I21: =H21+F38
A22: Jindal Steel | B22: ='[1]Production Capacity'!$H$16 | C22: =B22 | D22: =C22 | E22: =D22 | F22: =E22 | G22: =F22 | H22: =G22 | I22: =H22
A23: Jindal Stainless | B23: ='[1]Production Capacity'!$H$17 | C23: =B23 | D23: =C23+F41 | E23: =D23 | F23: =E23 | G23: =F23 | H23: =G23 | I23: =H23
A24: Others | B24: ='[1]Production Capacity'!$H$18 | C24: =$D$96-SUM(C19:C23) | D24: =$E$96-SUM(D19:D23) | E24: =$F$96-SUM(E19:E23) | F24: =$G$96-SUM(F19:F23) | G24: =$H$96-SUM(G19:G23) | H24: =$I$96-SUM(H19:H23) | I24: =$J$96-SUM(I19:I23)
A25: India Total | B25: =SUM(B19:B24) | C25: =SUM(C19:C24) | D25: =SUM(D19:D24) | E25: =SUM(E19:E24) | F25: =SUM(F19:F24) | G25: =SUM(G19:G24) | H25: =SUM(H19:H24) | I25: =SUM(I19:I24)
A28: Capacity Expansion Pipeline
A29: Project | B29: Company | C29: Type | D29: Start | E29: Completion | F29: Capacity (Mt) | G29: Status
A30: NINL Expansion | B30: Tata Steel | C30: Brownfield Int | D30: FY2027 | E30: FY2030 | F30: 4.8 | G30: Approved
A31: India Roadmap to 40 Mtpa | B31: Tata Steel | C31: Programme | D31: FY2027 | E31: FY2033 | F31: 5 | G31: Announced (Aspirational)
A32: Vijayanagar BF-3 Expansion | B32: JSW Steel | C32: Brownfield BF | D32: FY2026 | E32: FY2027 | F32: 1.5 | G32: Under Testing & Commissioning
A33: Vijayanagar Brownfield Expansion | B33: JSW Steel | C33: Brownfield Int | D33: FY2027 | E33: FY2030 | F33: 5 | G33: Board Approved
A34: Greenfield Integrated Plant JV | B34: JSW/POSCO | C34: Greenfield JV | D34: FY2027 | E34: FY2031 | F34: 6 | G34: Announced
A35: IISCO Steel Plant Expansion | B35: SAIL | C35: Greenfield | D35: FY2028 | E35: FY2031 | F35: 4.08 | G35: Board Approved
A36: Bokaro Steel Plant Expansion | B36: SAIL | C36: Brownfield | D36: FY2027 | E36: FY2030 | F36: 2.65 | G36: Board Approved
A37: Durgapur Steel Plant Expansion | B37: SAIL | C37: Brownfield | D37: FY2027 | E37: FY2029 | F37: 0.89 | G37: Board Approved
A38: Residual Ambition to 35 Mt | B38: SAIL | C38: Programme | D38: FY2028 | E38: FY2033 | F38: 8 | G38: Announced (Aspirational)
A39: Hazira Expansion (9→15 Mtpa) | B39: AM/NS India | C39: Brownfield Int | D39: FY2026 | E39: FY2029 | F39: 6 | G39: Under Implementation
A40: Rajayyapeta Phase 1 | B40: AM/NS India | C40: Greenfield | D40: FY2027 | E40: FY2032 | F40: 8.2 | G40: Announced
A41: Jajpur HARP | B41: JSL | C41: Downstream | D41: FY2025 | E41: FY2028 | F41: 1.27 | G41: In Progress
A42: Bokaro Capacity Doubling | B42: Electrosteel | C42: Brownfield | D42: FY2026 | E42: FY2027 | F42: 1.5 | G42: Announced by Parent
A45: Capacity Bridge
A46: Item | B46: FY27E | C46: FY28E | D46: FY29E | E46: FY30E | F46: FY31E | G46: FY32E | H46: FY33E
A47: Opening Capacity | B47: =C96 | C47: =B53 | D47: =C53 | E47: =D53 | F47: =E53 | G47: =F53 | H47: =G53
...

Sheet Capacity Expansion Tracker
A1: CAPACITY EXPANSION TRACKER
A2: Industry Financial Model | Indian Steel Industry | Horizon FY2027E-FY2033E | Base year FY2026A
H3: Active Scenario | I3: ='Control Panel'!$E$17
A4: OBJECTIVE
A5: The dated project pipeline that drives the capacity forecast. Twenty projects, each with its capacity, status, expected commissioning year and whether it counts towards INDIA's national crude steel capacity.
A7: Executive Summary
A8: KPI | B8: Value
A9: Total Active Projects | B9: =COUNTA($A$67:$A$86)
A10: Total Planned Capacity (Mtpa) | B10: =SUM($F$67:$F$86)
A11: Capacity Under Construction (Mtpa) | B11: =SUMIFS($F$67:$F$86,$H$67:$H$86,"Under*")
A12: Capacity Commissioned (Mtpa) | B12: =SUMIFS($F$67:$F$86,$H$67:$H$86,"Commissioned*")+SUMIFS($F$67:$F$86,$H$67:$H$86,"Completed*")
A13: Weighted Expected Capacity (Mtpa) | B13: =$D$91*'Model Assumptions'!$E$12
A14: Average Completion Probability | B14: ='Model Assumptions'!$E$12
A15: Average Project Size (Mtpa) | B15: =IFERROR(SUM($F$67:$F$86)/COUNT($F$67:$F$86),"")
A18: Master Project Resigter
A19: Project ID | B19: Company | C19: Plant | D19: State | E19: Route | F19: Project Type | G19: Existing Capacity | H19: Expansion Capacity | I19: Total Capacity | J19: Announcement | K19: COD | L19: Probability | M19: Status | N19: Capex (₹ Cr) | O19: Source
A20: P01 | B20: =$B$67 | C20: =$C$67 | D20: =$D$67 | E20: =IF(ISNUMBER(SEARCH("EAF",$E$67)),"EAF",IF(ISNUMBER(SEARCH("BF",$E$67)),"BF-BOF",IF(ISNUMBER(SEARCH("integrated",$E$67)),"BF-BOF (integrated)",IF(ISNUMBER(SEARCH("melt",$G$67)),"Stainless melt","Not specified")))) | F20: =$E$67 | H20: =$F$67 | K20: =$I$67 | L20: =IF($L67="Yes",'Model Assumptions'!$E$12,0) | M20: =$H$67 | N20: =$J$67 | O20: =$M$67
A21: P02 | B21: =$B$68 | C21: =$C$68 | D21: =$D$68 | E21: =IF(ISNUMBER(SEARCH("EAF",$E$68)),"EAF",IF(ISNUMBER(SEARCH("BF",$E$68)),"BF-BOF",IF(ISNUMBER(SEARCH("integrated",$E$68)),"BF-BOF (integrated)",IF(ISNUMBER(SEARCH("melt",$G$68)),"Stainless melt","Not specified")))) | F21: =$E$68 | H21: =$F$68 | K21: =$I$68 | L21: =IF($L68="Yes",'Model Assumptions'!$E$12,0) | M21: =$H$68 | N21: =$J$68 | O21: =$M$68
A22: P03 | B22: =$B$69 | C22: =$C$69 | D22: =$D$69 | E22: =IF(ISNUMBER(SEARCH("EAF",$E$69)),"EAF",IF(ISNUMBER(SEARCH("BF",$E$69)),"BF-BOF",IF(ISNUMBER(SEARCH("integrated",$E$69)),"BF-BOF (integrated)",IF(ISNUMBER(SEARCH("melt",$G$69)),"Stainless melt","Not specified")))) | F22: =$E$69 | H22: =$F$69 | K22: =$I$69 | L22: =IF($L69="Yes",'Model Assumptions'!$E$12,0) | M22: =$H$69 | N22: =$J$69 | O22: =$M$69
A23: P04 | B23: =$B$70 | C23: =$C$70 | D23: =$D$70 | E23: =IF(ISNUMBER(SEARCH("EAF",$E$70)),"EAF",IF(ISNUMBER(SEARCH("BF",$E$70)),"BF-BOF",IF(ISNUMBER(SEARCH("integrated",$E$70)),"BF-BOF (integrated)",IF(ISNUMBER(SEARCH("melt",$G$70)),"Stainless melt","Not specified")))) | F23: =$E$70 | H23: =$F$70 | K23: =$I$70 | L23: =IF($L70="Yes",'Model Assumptions'!$E$12,0) | M23: =$H$70 | N23: =$J$70 | O23: =$M$70
A24: P05 | B24: =$B$71 | C24: =$C$71 | D24: =$D$71 | E24: =IF(ISNUMBER(SEARCH("EAF",$E$71)),"EAF",IF(ISNUMBER(SEARCH("BF",$E$71)),"BF-BOF",IF(ISNUMBER(SEARCH("integrated",$E$71)),"BF-BOF (integrated)",IF(ISNUMBER(SEARCH("melt",$G$71)),"Stainless melt","Not specified")))) | F24: =$E$71 | H24: =$F$71 | K24: =$I$71 | L24: =IF($L71="Yes",'Model Assumptions'!$E$12,0) | M24: =$H$71 | N24: =$J$71 | O24: =$M$71
A25: P06 | B25: =$B$72 | C25: =$C$72 | D25: =$D$72 | E25: =IF(ISNUMBER(SEARCH("EAF",$E$72)),"EAF",IF(ISNUMBER(SEARCH("BF",$E$72)),"BF-BOF",IF(ISNUMBER(SEARCH("integrated",$E$72)),"BF-BOF (integrated)",IF(ISNUMBER(SEARCH("melt",$G$72)),"Stainless melt","Not specified")))) | F25: =$E$72 | H25: =$F$72 | K25: =$I$72 | L25: =IF($L72="Yes",'Model Assumptions'!$E$12,0) | M25: =$H$72 | N25: =$J$72 | O25: =$M$72
A26: P07 | B26: =$B$73 | C26: =$C$73 | D26: =$D$73 | E26: =IF(ISNUMBER(SEARCH("EAF",$E$73)),"EAF",IF(ISNUMBER(SEARCH("BF",$E$73)),"BF-BOF",IF(ISNUMBER(SEARCH("integrated",$E$73)),"BF-BOF (integrated)",IF(ISNUMBER(SEARCH("melt",$G$73)),"Stainless melt","Not specified")))) | F26: =$E$73 | H26: =$F$73 | K26: =$I$73 | L26: =IF($L73="Yes",'Model Assumptions'!$E$12,0) | M26: =$H$73 | N26: =$J$73 | O26: =$M$73
A27: P08 | B27: =$B$74 | C27: =$C$74 | D27: =$D$74 | E27: =IF(ISNUMBER(SEARCH("EAF",$E$74)),"EAF",IF(ISNUMBER(SEARCH("BF",$E$74)),"BF-BOF",IF(ISNUMBER(SEARCH("integrated",$E$74)),"BF-BOF (integrated)",IF(ISNUMBER(SEARCH("melt",$G$74)),"Stainless melt","Not specified")))) | F27: =$E$74 | H27: =$F$74 | K27: =$I$74 | L27: =IF($L74="Yes",'Model Assumptions'!$E$12,0) | M27: =$H$74 | N27: =$J$74 | O27: =$M$74
