Workbook
Name ScenID: '01 Control Panel'!$D$15
Name ScenarioName: '01 Control Panel'!$D$14

Sheet Cover
B2: INDUSTRY FINANCIAL MODEL
B3: INDIAN STEEL INDUSTRY - ANALYTICAL ENGINE
B5: Global Metals & Mining Research
B6: Forecast horizon FY2027E-FY2033E (7 years) | Base year FY2026A | Built 03 August 2026
B8: WHAT THIS MODEL IS
B9: An analytical engine, not a database. It consumes FY2026 actuals from Master Industry Database.xlsx and forecasts Indian steel demand, supply, capacity, utilisation, prices, costs, revenue, EBITDA, working capital, cash flow and trade to FY2033, under four fully integrated scenarios. It is the parent model for single-name DCF, trading and transaction comparables, EV per tonne, replacement cost and ROIC work on Tata Steel, JSW Steel, SAIL, Jindal Steel, Jindal Stainless and AM/NS India.
B11: HOW SCENARIOS WORK
B12: Change one cell - the scenario selector on 01 Control Panel - and the entire workbook re-computes. The selector drives a named range ScenID, which every driver on 02 Model Assumptions resolves through an INDEX across its four scenario rows. No sheet contains a scenario-specific hardcode. There is nothing else to change.
B14: THE ONE THING THAT MAKES THIS AN ENGINE RATHER THAN A SPREADSHEET
B15: A lagged price-utilisation feedback (driver D23). Effective realisation is adjusted by an elasticity applied to the gap between the PRIOR year's capacity utilisation and normal utilisation. Because it is lagged there is no circular reference, but it means capacity, pipeline delivery rates and secondary-sector additions genuinely transmit into price and therefore EBITDA. Without it, capacity would be decorative and the capacity drivers would show literally zero EBITDA sensitivity. It also produces the economically correct and counter-intuitive result that FASTER capacity delivery is EBITDA-NEGATIVE, because it depresses utilisation and therefore price.
B17: INDEPENDENT VALIDATION OF THE CAPACITY BLOCK
B18: Built bottom-up from a dated 20-project tracker plus a secondary-sector residual, the model produces India crude steel capacity of 302.0 Mtpa in FY2031 against the National Steel Policy 2017 target of 300 Mtpa - within 0.7%. The model was not calibrated to that target, so this is a genuine external check.
... B29: Public sources only. No non-public or price-sensitive information.

Sheet Contents
B1: CONTENTS
B2: Click a sheet name to navigate.
A4: # | B4: Worksheet | C4: Purpose and principal content | D4: Type
A5: 00 | B5: 00 Database Import | C5: The controlled boundary with Master Industry Database.xlsx: 18 FY2026 anchors with exact provenance and a documented refresh procedure. | D5: Input
A6: 0H | B6: 0H Forecast Horizon | C6: Weighted evaluation of 5, 7 and 10-year horizons; 7 years selected. Live weighted-score formulas. | D6: Documentation
A7: 01 | B7: 01 Control Panel | C7: The scenario selector - the only cell a user changes - plus a live output panel. | D7: Control
A8: 02 | B8: 02 Model Assumptions | C8: 26 drivers on 4 scenarios, the active resolved block, the 13-field assumption register and the WACC build-up. | D8: Input
A9: 03 | B9: 03 Macroeconomic Model | C9: Real GDP, CPI, USD/INR, G-sec yield and WACC. | D9: Calc
A10: 04 | B10: 04 Steel Demand Model | C10: Consumption via GDP times a history-calibrated elasticity; per capita intensity. | D10: Calc
A11: 05 | B11: 05 Steel Supply Model | C11: The JPC supply identity, the capacity ceiling and the shortfall routed to imports. | D11: Calc
A12: 06 | B12: 06 Capacity Forecast | C12: Capacity from the project tracker plus a secondary residual; validated against the 300 Mtpa policy target. | D12: Calc
A13: 07 | B13: 07 Capacity Expansion Tracker | C13: 20 dated projects with live SUMIFS feeding 06; encodes the acquisition, downstream and overseas exclusions. | D13: Input
A14: 08 | B14: 08 Capacity Utilisation | C14: Utilisation and the utilisation gap that drives the price feedback. | D14: Calc
A15: 09 | B15: 09 Steel Price Forecast | C15: Blended realisation with the lagged utilisation feedback; safeguard duty schedule. | D15: Calc
... A32: 26 | B32: 26 Sources | C32: Sources for the forward-looking assumptions, plus the model change log. | D32: Documentation

Sheet 00 Database Import
B1: 00 Database Import
B2: Industry Financial Model | Indian Steel Industry | Horizon FY2027E-FY2033E | Base year FY2026A | Built 03-Aug-2026
B4: OBJECTIVE
B5: The single controlled boundary between Master Industry Database.xlsx and this model. Every FY2026 actual the model uses enters here, once, with its exact location in the database recorded. Nothing downstream references the database directly.
B6: METHODOLOGY
B7: DESIGN CHOICE, STATED EXPLICITLY. Values are imported as static numbers with full provenance rather than as live external-workbook links. Live links to another file are an operational risk in a model that will be circulated - they break on move or rename, they prompt on open, and they silently return stale values if the source is unavailable. Instead each row records the database sheet and the exact line it came from, and the 'Refresh formula' column contains the external-link formula as TEXT, ready to paste if a live link is wanted. The refresh procedure is at the foot of this sheet. Every value here was extracted programmatically from the database file at build time, so a transcription error is structurally impossible.
B8: UNITS
B9: As stated per row.
B10: DEPENDENCIES
B11: Source: Master Industry Database.xlsx. Consumed by every forecast sheet.
A13: ID | B13: Imported item | C13: Unit | D13: FY2026A value | E13: Master Database location | F13: Source ID in database | G13: Refresh formula (paste to activate a live link) | H13: Confidence | I13: Notes
A14: A01 | B14: India crude steel production | C14: Mt | D14: 168.42 | E14: Master DB > Production Volume > India crude steel production > FY2026 | F14: S01 | G14: ='[Master Industry Database.xlsx]Production Volume'!<cell> | H14: High
A15: A02 | B15: India total finished steel production | C15: Mt | D15: 160.94 | E15: Master DB > Demand & Consumption > supply balance (April-2026 JPC vintage) > FY2026 | F15: S01 | G15: ='[Master Industry Database.xlsx]Demand & Consumption'!<cell> | H15: High | I15: Master DB > Demand & Consumption > supply balance (April-2026 JPC vintage) > FY2026. VINTAGE CHOICE: the model uses the April-2026 vintage throughout because that balance is internally self-reconciling (production + imports - exports - stock change = consumption), which a forecast identity requires. The June-2026 vintage figure of 161.74 Mt is carried as a reconciliation memo. This is the resolution the database itself recommends for the supply balance under Conflict C03
A16: A03 | B16: India apparent finished steel consumption | C16: Mt | D16: 163.74 | E16: Master DB > Demand & Consumption > supply balance (April-2026 JPC vintage) > FY2026 | F16: S01 | G16: ='[Master Industry Database.xlsx]Demand & Consumption'!<cell> | H16: High | I16: Master DB > Demand & Consumption > supply balance (April-2026 JPC vintage) > FY2026. June-2026 vintage is 164.19 Mt - carried as a memo. See A02 on the vintage choice
A17: A04 | B17: India crude steel capacity | C17: Mtpa | D17: 220.4 | E17: Master DB > Production Capacity > India crude steel capacity > FY2026 | F17: S02/S03 | G17: ='[Master Industry Database.xlsx]Production Capacity'!<cell> | H17: High
A18: A05 | B18: India finished steel imports | C18: Mt | D18: 6.524 | E18: Master DB > Imports & Exports > FY2026 | F18: S02 | G18: ='[Master Industry Database.xlsx]Imports & Exports'!<cell> | H18: High
A19: A06 | B19: India finished steel exports | C19: Mt | D19: 6.602 | E19: Master DB > Imports & Exports > FY2026 | F19: S02 | G19: ='[Master Industry Database.xlsx]Imports & Exports'!<cell> | H19: High
A20: A07 | B20: Variation in stock | C20: Mt | D20: -2.88 | E20: Master DB > Demand & Consumption > supply balance line 6 > FY2026 | F20: S01 | G20: ='[Master Industry Database.xlsx]Demand & Consumption'!<cell> | H20: High
A21: A08 | B21: Crude-to-finished steel ratio | C21: x | D21: 1.04647 | E21: Derived: 168.42 / 160.94, both on the April-2026 JPC vintage, so the ratio is internally consistent with the supply balance the model uses. On the June-2026 vintage (168.42 / 161.74) the ratio would be 1.0413 - a 0.5% difference | F21: S01 | G21: ='[Master Industry Database.xlsx]Sheet'!<cell> | H21: High | I21: Derived: 168.42 / 160.94, both on the April-2026 JPC vintage, so the ratio is internally consistent with the supply balance the model uses. On the June-2026 vintage (168.42 / 161.74) the ratio would be 1.0413 - a 0.5% difference
A22: A09 | B22: Blended industry realisation | C22: Rs/t | D22: 59974 | E22: Derived: volume-weighted revenue / volume for Tata Steel India, JSW Steel India, SAIL and Jindal Steel from Master DB (Rs 4,79,191 cr / 79.90 Mt x 10) | F22: S08/S09/S10/S11 | G22: ='[Master Industry Database.xlsx]Sheet'!<cell> | H22: High | I22: Derived: volume-weighted revenue / volume for Tata Steel India, JSW Steel India, SAIL and Jindal Steel from Master DB (Rs 4,79,191 cr / 79.90 Mt x 10)
A23: A10 | B23: Weighted EBITDA per tonne | C23: Rs/t | D23: 10733 | E23: Derived: volume-weighted EBITDA/t across the same four majors from Master DB | F23: S08-S11 | G23: ='[Master Industry Database.xlsx]Sheet'!<cell> | H23: High | I23: Derived: volume-weighted EBITDA/t across the same four majors from Master DB
A24: A11 | B24: Implied cash cost per tonne | C24: Rs/t | D24: 49241 | E24: Derived: A09 less A10. Reconciliation: A10 x 79.90 Mt = Rs 85,759 cr against the Rs 86,318 cr sum of the four reported EBITDAs, a 0.6% rounding difference | F24: Derived | G24: ='[Master Industry Database.xlsx]Sheet'!<cell> | H24: High | I24: Derived: A09 less A10. Reconciliation: A10 x 79.90 Mt = Rs 85,759 cr against the Rs 86,318 cr sum of the four reported EBITDAs, a 0.6% rounding difference
A25: A12 | B25: Weighted EBITDA margin | C25: % | D25: 0.179 | E25: Derived: A10 / A09 | F25: Derived | G25: ='[Master Industry Database.xlsx]Sheet'!<cell> | H25: High | I25: Derived: A10 / A09
A26: A13 | B26: Calibration volume coverage | C26: Mt | D26: 79.9 | E26: Sum of FY2026 volumes for the four majors = 49.4% of India finished steel production | F26: S08-S11 | G26: ='[Master Industry Database.xlsx]Sheet'!<cell> | H26: High
A27: A14 | B27: India per capita consumption | C27: kg | D27: 115.7 | E27: Master DB > Demand & Consumption > per capita > FY2026 | F27: S03 | G27: ='[Master Industry Database.xlsx]Demand & Consumption'!<cell> | H27: High
A28: A15 | B28: Iron ore 62% Fe CFR China, FY2026 average | C28: US$/dmt | D28: 100.52 | E28: Master DB > Iron Ore Prices > fiscal-year averages > FY2026 | F28: S17 | G28: ='[Master Industry Database.xlsx]Iron Ore Prices'!<cell> | H28: High
A29: A16 | B29: Australian thermal coal, FY2026 average | C29: US$/mt | D29: 111.5 | E29: Master DB > Coking Coal Prices > thermal reference > FY2026 | F29: S17 | G29: ='[Master Industry Database.xlsx]Coking Coal Prices'!<cell> | H29: High
A30: A17 | B30: Premium HCC coking coal, Mar-2026 spot reference | C30: US$/t | D30: 225 | E30: Master DB > Coking Coal Prices > Ministry of Steel assessment > Mar-2026. NOT a fiscal-year average - none is asserted in the database (Conflict C01) | F30: S01 | G30: ='[Master Industry Database.xlsx]Coking Coal Prices'!<cell> | H30: High
A31: A18 | B31: Domestic HRC, end-Mar-2026 | C31: Rs/t | D31: 57700 | E31: Master DB > Steel Prices > ICRA end-Mar-2026 assessment | F31: S19 | G31: ='[Master Industry Database.xlsx]Steel Prices'!<cell> | H31: High
B33: REFRESH PROCEDURE. (1) Open both workbooks. (2) For each row, read the value at the stated Master Database location. (3) Compare against column D. (4) If different, overwrite column D and record the change in the model change log on 26 Sources. (5) Re-run 25 Audit Checks. Nothing else needs to change: every downstream sheet references this sheet, so a single correction propagates.
B35: DERIVED IMPORTS. A09 to A13 and A08 are DERIVED from database figures rather than lifted from a single cell, and their derivation is stated in the Notes column. They are imported here rather than computed downstream so that the calibration of the entire model sits in one auditable place.
B37: VINTAGE. The model uses the April-2026 Joint Plant Committee vintage for the supply balance because that balance is internally self-reconciling - production plus imports less exports less stock change equals consumption - which a forecast identity requires. The database's June-2026 vintage figures (finished production 161.74 Mt, consumption 164.19 Mt) are carried as reconciliation memos. This is the resolution the database itself recommends under its Conflict C03.

Sheet 0H Forecast Horizon
B1: 0H Forecast Horizon
B2: Industry Financial Model | Indian Steel Industry | Horizon FY2027E-FY2033E | Base year FY2026A | Built 03-Aug-2026
B4: OBJECTIVE
B5: Evaluates 5-year, 7-year and 10-year forecast horizons against weighted criteria and selects one. The selected horizon is applied identically on every forecast sheet in the workbook.
B6: METHODOLOGY
B7: Five criteria, weighted. Each option is scored 1 to 5 against each criterion. The weighted total is a live formula, not a hardcoded result, so a reviewer who disagrees with a weight can change it and see whether the conclusion survives.
B8: UNITS
B9: Scores 1 (worst) to 5 (best). Weights sum to 1.00.
B10: DEPENDENCIES
B11: Determines the column structure of every forecast sheet.
A13: Criterion | B13: Weight | C13: 5-Year (FY2027-FY2031) | D13: 7-Year (FY2027-FY2033) | E13: 10-Year (FY2027-FY2036) | F13: Score 5Y | G13: Score 7Y | H13: Score 10Y | I13: Basis of assessment / evidence
A14: Coverage of the announced capacity pipeline | B14: 0.25 | C14: Ends FY2031, exactly the terminal year of the announced pipeline. Captures 100% of commissioning but 0 years of post-commissioning ramp. | D14: Ends FY2033. Captures 100% of commissioning PLUS a 2-year ramp tail, so the terminal year reflects normalised rather than ramping utilisation. | E14: Ends FY2036, five years beyond the last dated project. Years 8-10 have no project-level visibility and become pure extrapolation. | F14: 3 | G14: 5 | H14: 2 | I14: Dated pipeline in the Master Database terminates FY2031: POSCO-JSW 6 Mtpa greenfield by 2031, SAIL ~35 Mt ambition by FY2031, PLI 1.2 capacity 8.7 Mt by FY2031, National Steel Policy 2017 target year FY2031. No credible dated project extends beyond FY2031.
A15: Terminal year is a normalised, valuation-usable year | B15: 0.25 | C15: NO. Capacity commissioned FY2030-FY2031 is still ramping in FY2031, so terminal-year utilisation is artificially depressed and a terminal value struck there is understated. | D15: YES. The FY2030-FY2031 capacity cohort reaches normalised utilisation by FY2033 on a 2-3 year ramp, so the terminal year is a fair steady state. | E15: YES but redundant - steady state is already reached by FY2033, so FY2034-FY2036 add extrapolation risk without adding information. | F15: 1 | G15: 5 | H15: 4 | I15: Greenfield and large brownfield Indian steel capacity historically takes 2-3 years from commissioning to normalised utilisation. Observed in the database: NMDC Steel Nagarnar (3 Mtpa) produced 1.471 Mt in FY2025 and 2.382 Mt in FY2026, i.e. ~79% of nameplate in year 3+; RINL required a full year to recover to 5.43 Mt.
A16: Coverage of a complete industry cycle | B16: 0.2 | C16: ~0.7 cycles. Truncates the cycle, so the average forecast year is not cycle-neutral and the result is highly sensitive to where the start point sits in the cycle. | D16: ~1.0 cycle. The forecast average is approximately cycle-neutral, which is the property a mid-cycle valuation requires. | E16: ~1.4 cycles. Cycle-neutral but the second partial cycle is unforecastable in its timing. | F16: 2 | G16: 5 | H16: 3 | I16: Observed cycle length in the database: standardised EBITDA margin for Tata Steel peaked at 26% in FY2022, troughed at 10% in FY2024 and recovered to 15% in FY2026 - a 4-year peak-to-trough leg implying a ~7-8 year full cycle. Coking coal peaked at US$354/t in Oct-2023 and troughed at ~US$175/t in Mar-2025; iron ore peaked at US$155.52/dmt in FY2022 and troughed at US$100.52/dmt in FY2026.
A17: Reliability of the macro anchor | B17: 0.15 | C17: Strong. RBI publishes an explicit FY2027 projection and the IMF medium-term path is credible to roughly 5 years. | D17: Adequate. Years 6-7 rely on a converging steady-state growth assumption rather than a published projection, which is disclosed and sensitised. | E17: Weak. Years 8-10 require a GDP path with no institutional publisher support at all. | F17: 5 | G17: 4 | H17: 2 | I17: RBI's June-2026 MPC projects FY2027 real GDP growth at 6.6%. No official Indian source publishes a real GDP path beyond roughly 5 years, so any year past FY2031 is the modeller's own convergence assumption.
A18: Usability for DCF terminal value | B18: 0.15 | C18: Poor. A terminal value struck on a non-normalised year requires a manual mid-cycle adjustment, which defeats the purpose of an explicit forecast period. | D18: Good. Terminal value can be struck directly off FY2033 with no manual normalisation. | E18: Good but the incremental years add estimation error to the discounted stub, where their present-value weight is small. | F18: 2 | G18: 5 | H18: 3 | I18: At a ~12% nominal WACC the present-value weight of forecast years 8-10 is under 12% of total enterprise value, so extending the horizon adds materially more estimation error than valuation information.
A19: WEIGHTED TOTAL | B19: =SUM(B14:B18) | F19: =SUMPRODUCT($B$14:$B$18,F14:F18) | G19: =SUMPRODUCT($B$14:$B$18,G14:G18) | H19: =SUMPRODUCT($B$14:$B$18,H14:H18) | I19: Live formula. The 7-year option wins on four of five criteria and ties on none; it loses only on macro-anchor reliability, where the 5-year option is stronger.
A21: SELECTED: 7 YEARS - FY2027E to FY2033E
A23: SELECTED HORIZON: 7 YEARS - FY2027E to FY2033E, with FY2026A as the base year.
A25: Weighted score: 7-year 4.85 against 5-year 2.55 and 10-year 2.75 (weights and criterion scores are shown live in the table above and the weighted total is a formula, not a hard-coded number).
A27: The decisive consideration is that the 5-year horizon ends in FY2031 - the same year the announced capacity pipeline finishes commissioning - so its terminal year embeds artificially low utilisation and would understate terminal value. The 7-year horizon adds the two-year ramp tail needed for the FY2030-FY2031 capacity cohort to reach normalised utilisation, and in doing so also spans approximately one full industry cycle, which makes the forecast average cycle-neutral. The 10-year horizon buys no additional information: steady state is already reached by FY2033, no dated project extends beyond FY2031, no institutional source publishes an Indian GDP path that far out, and forecast years 8-10 carry under 12% of present value at a ~12% nominal WACC while carrying the highest estimation error in the model.
A29: This horizon is applied consistently on every forecast worksheet. Columns E to K are FY2027E to FY2033E throughout the workbook without exception.

Sheet 01 Control Panel
B1: 01 Control Panel
B2: Industry Financial Model | Indian Steel Industry | Horizon FY2027E-FY2033E | Base year FY2026A | Built 03-Aug-2026
B4: OBJECTIVE
B5: The only cell in this workbook a user needs to change. The scenario selector drives every forecast on every sheet.
B6: METHODOLOGY
B7: The selector is a validated dropdown. It resolves to the named range ScenID via MATCH against the scenario list below. Every driver on 02 Model Assumptions uses INDEX with ScenID to pick its active row. Consequently no sheet anywhere in the workbook contains a scenario-specific hardcode.
B8: UNITS
B9: As stated per row.
B10: DEPENDENCIES
B11: Drives 02 Model Assumptions and therefore every sheet from 03 to 24.
B13: SCENARIO SELECTOR
B14: Active scenario | D14: Base Case | O14: CHANGE THIS CELL ONLY. Dropdown-validated. Everything else recomputes.
B15: Scenario index (ScenID) | D15: =MATCH(D$14,D$17:D$20,0) | O15: Named range ScenID. Resolves the selector to 1-4 for the INDEX lookups on 02 Model Assumptions.
B17: Scenario list (do not reorder - ScenID depends on this order)
B18: 1. | D18: Base Case | O18: Central case. RBI FY2027 GDP of 6.6%, realisation calibrated to a FY2033 industry margin of 16.8%.
B19: 2. | D19: Bull Case | O19: Demand-led upcycle. Peaks at a 26.0% industry margin in FY2030, matching the FY2022 cycle peak.
B20: 3. | D20: Bear Case | O20: Demand-led downturn. Raw materials FALL with demand, so margins compress to 7-11% rather than collapsing.
B21: 4. | D21: Stress Case | O21: Stagflationary supply shock plus demand shock. Coking coal to US$300/t, INR to 113. Troughs at -9.2% in FY2028.
B23: LIVE MODEL OUTPUT - ACTIVE SCENARIO
B24: Line item | C24: Unit | D24: FY2026A | E24: FY2027E | F24: FY2028E | G24: FY2029E | H24: FY2030E | I24: FY2031E | J24: FY2032E | K24: FY2033E | L24: CAGR | M24: Source | N24: Conf. | O24: Notes / methodology
B25: India finished steel consumption | C25: Mt | D25: =IF(ISBLANK('04 Steel Demand Model'!D$17),"n/a",'04 Steel Demand Model'!D$17) | E25: ='04 Steel Demand Model'!E$17 | F25: ='04 Steel Demand Model'!F$17 | G25: ='04 Steel Demand Model'!G$17 | H25: ='04 Steel Demand Model'!H$17 | I25: ='04 Steel Demand Model'!I$17 | J25: ='04 Steel Demand Model'!J$17 | K25: ='04 Steel Demand Model'!K$17 | L25: =IFERROR(IF(AND(ISNUMBER(D25),ISNUMBER(K25),D25>0),(K25/D25)^(1/7)-1,""),"") | M25: 04
B26: India crude steel production | C26: Mt | D26: =IF(ISBLANK('05 Steel Supply Model'!D$25),"n/a",'05 Steel Supply Model'!D$25) | E26: ='05 Steel Supply Model'!E$25 | F26: ='05 Steel Supply Model'!F$25 | G26: ='05 Steel Supply Model'!G$25 | H26: ='05 Steel Supply Model'!H$25 | I26: ='05 Steel Supply Model'!I$25 | J26: ='05 Steel Supply Model'!J$25 | K26: ='05 Steel Supply Model'!K$25 | L26: =IFERROR(IF(AND(ISNUMBER(D26),ISNUMBER(K26),D26>0),(K26/D26)^(1/7)-1,""),"") | M26: 05
B27: India crude steel capacity | C27: Mtpa | D27: =IF(ISBLANK('06 Capacity Forecast'!D$20),"n/a",'06 Capacity Forecast'!D$20) | E27: ='06 Capacity Forecast'!E$20 | F27: ='06 Capacity Forecast'!F$20 | G27: ='06 Capacity Forecast'!G$20 | H27: ='06 Capacity Forecast'!H$20 | I27: ='06 Capacity Forecast'!I$20 | J27: ='06 Capacity Forecast'!J$20 | K27: ='06 Capacity Forecast'!K$20 | L27: =IFERROR(IF(AND(ISNUMBER(D27),ISNUMBER(K27),D27>0),(K27/D27)^(1/7)-1,""),"") | M27: 06
B28: Capacity utilisation | C28: % | D28: =IF(ISBLANK('08 Capacity Utilisation'!D$16),"n/a",'08 Capacity Utilisation'!D$16) | E28: ='08 Capacity Utilisation'!E$16 | F28: ='08 Capacity Utilisation'!F$16 | G28: ='08 Capacity Utilisation'!G$16 | H28: ='08 Capacity Utilisation'!H$16 | I28: ='08 Capacity Utilisation'!I$16 | J28: ='08 Capacity Utilisation'!J$16 | K28: ='08 Capacity Utilisation'!K$16 | L28: =IFERROR(IF(AND(ISNUMBER(D28),ISNUMBER(K28),D28>0),(K28/D28)^(1/7)-1,""),"") | M28: 08
B29: Blended realisation | C29: Rs/t | D29: =IF(ISBLANK('09 Steel Price Forecast'!D$22),"n/a",'09 Steel Price Forecast'!D$22) | E29: ='09 Steel Price Forecast'!E$22 | F29: ='09 Steel Price Forecast'!F$22 | G29: ='09 Steel Price Forecast'!G$22 | H29: ='09 Steel Price Forecast'!H$22 | I29: ='09 Steel Price Forecast'!I$22 | J29: ='09 Steel Price Forecast'!J$22 | K29: ='09 Steel Price Forecast'!K$22 | L29: =IFERROR(IF(AND(ISNUMBER(D29),ISNUMBER(K29),D29>0),(K29/D29)^(1/7)-1,""),"") | M29: 09
B30: Cash cost per tonne | C30: Rs/t | D30: =IF(ISBLANK('11 Cost Curve'!D$17),"n/a",'11 Cost Curve'!D$17) | E30: ='11 Cost Curve'!E$17 | F30: ='11 Cost Curve'!F$17 | G30: ='11 Cost Curve'!G$17 | H30: ='11 Cost Curve'!H$17 | I30: ='11 Cost Curve'!I$17 | J30: ='11 Cost Curve'!J$17 | K30: ='11 Cost Curve'!K$17 | L30: =IFERROR(IF(AND(ISNUMBER(D30),ISNUMBER(K30),D30>0),(K30/D30)^(1/7)-1,""),"") | M30: 11
B31: EBITDA per tonne | C31: Rs/t | D31: =IF(ISBLANK('13 EBITDA Model'!D$16),"n/a",'13 EBITDA Model'!D$16) | E31: ='13 EBITDA Model'!E$16 | F31: ='13 EBITDA Model'!F$16 | G31: ='13 EBITDA Model'!G$16 | H31: ='13 EBITDA Model'!H$16 | I31: ='13 EBITDA Model'!I$16 | J31: ='13 EBITDA Model'!J$16 | K31: ='13 EBITDA Model'!K$16 | L31: =IFERROR(IF(AND(ISNUMBER(D31),ISNUMBER(K31),D31>0),(K31/D31)^(1/7)-1,""),"") | M31: 13
B32: Industry EBITDA margin | C32: % | D32: =IF(ISBLANK('14 Margin Analysis'!D$17),"n/a",'14 Margin Analysis'!D$17) | E32: ='14 Margin Analysis'!E$17 | F32: ='14 Margin Analysis'!F$17 | G32: ='14 Margin Analysis'!G$17 | H32: ='14 Margin Analysis'!H$17 | I32: ='14 Margin Analysis'!I$17 | J32: ='14 Margin Analysis'!J$17 | K32: ='14 Margin Analysis'!K$17 | L32: =IFERROR(IF(AND(ISNUMBER(D32),ISNUMBER(K32),D32>0),(K32/D32)^(1/7)-1,""),"") | M32: 14
B33: Industry revenue | C33: Rs cr | D33: =IF(ISBLANK('12 Revenue Forecast'!D$16),"n/a",'12 Revenue Forecast'!D$16) | E33: ='12 Revenue Forecast'!E$16 | F33: ='12 Revenue Forecast'!F$16 | G33: ='12 Revenue Forecast'!G$16 | H33: ='12 Revenue Forecast'!H$16 | I33: ='12 Revenue Forecast'!I$16 | J33: ='12 Revenue Forecast'!J$16 | K33: ='12 Revenue Forecast'!K$16 | L33: =IFERROR(IF(AND(ISNUMBER(D33),ISNUMBER(K33),D33>0),(K33/D33)^(1/7)-1,""),"") | M33: 12
B34: Industry EBITDA | C34: Rs cr | D34: =IF(ISBLANK('13 EBITDA Model'!D$18),"n/a",'13 EBITDA Model'!D$18) | E34: ='13 EBITDA Model'!E$18 | F34: ='13 EBITDA Model'!F$18 | G34: ='13 EBITDA Model'!G$18 | H34: ='13 EBITDA Model'!H$18 | I34: ='13 EBITDA Model'!I$18 | J34: ='13 EBITDA Model'!J$18 | K34: ='13 EBITDA Model'!K$18 | L34: =IFERROR(IF(AND(ISNUMBER(D34),ISNUMBER(K34),D34>0),(K34/D34)^(1/7)-1,""),"") | M34: 13
B35: Unlevered free cash flow | C35: Rs cr | D35: =IF(ISBLANK('16 Cash Flow Model'!D$32),"n/a",'16 Cash Flow Model'!D$32) | E35: ='16 Cash Flow Model'!E$32 | F35: ='16 Cash Flow Model'!F$32 | G35: ='16 Cash Flow Model'!G$32 | H35: ='16 Cash Flow Model'!H$32 | I35: ='16 Cash Flow Model'!I$32 | J35: ='16 Cash Flow Model'!J$32 | K35: ='16 Cash Flow Model'!K$32 | L35: =IFERROR(IF(AND(ISNUMBER(D35),ISNUMBER(K35),D35>0),(K35/D35)^(1/7)-1,""),"") | M35: 16
B36: Every figure above is a live link. Change the selector and this panel, and every other sheet, recomputes.

Sheet 02 Model Assumptions
B1: 02 Model Assumptions
B2: Industry Financial Model | Indian Steel Industry | Horizon FY2027E-FY2033E | Base year FY2026A | Built 03-Aug-2026
B4: OBJECTIVE
B5: Every driver in the model, on all four scenarios, with the full evidence base. Section B resolves the active scenario and is the ONLY block the rest of the workbook reads.
B6: METHODOLOGY
B7: Section A holds the raw scenario matrix: four rows per driver, one per scenario, in a fixed order. Section B holds one row per driver whose forecast cells are =INDEX(<the four scenario cells in this column>, ScenID). Downstream sheets reference Section B only. Section C is the assumption register carrying the mandated thirteen fields. Section D shows the WACC build-up cell by cell rather than as a single number, so a reviewer can substitute house assumptions in one place.
B8: UNITS
B9: As stated per row. Percentages are stored as decimals.
B10: DEPENDENCIES
B11: Reads ScenID from 01 Control Panel. Read by every sheet from 03 to 24.
B13: SECTION A - SCENARIO DRIVER MATRIX (raw input; not read downstream)
A14: ID | B14: Driver | C14: Unit | D14: Scenario | E14: FY2027E | F14: FY2028E | G14: FY2029E | H14: FY2030E | I14: FY2031E | J14: FY2032E | K14: FY2033E | M14: Source | N14: Conf. | O14: Evidence and reasoning
A15: D01 | B15: India real GDP growth | C15: % | D15: Base Case | E15: 0.066 | F15: 0.068 | G15: 0.068 | H15: 0.067 | I15: 0.067 | J15: 0.065 | K15: 0.065 | M15: RBI-Jun26 | N15: High | O15: RBI Monetary Policy Committee, 05-Jun-2026, projects FY2027 real GDP growth at 6.6%, revised down from 6.9% in Apr-2026 on West Asia conflict, energy prices and monsoon risk; FY2026 estimated at 7.6%; Q4FY2026 actual 7.7%. Base case adopts the RBI FY2027 figure unchanged, then converges to a 6.5% steady state. Bull adds ~80bps on the RBI's own stated sensitivity that growth 'could top 7% if oil prices fall further'. Stress applies a 220bps FY2027 shock, comparable in magnitude to a global recession year.
D16: Bull Case | E16: 0.074 | F16: 0.076 | G16: 0.075 | H16: 0.074 | I16: 0.073 | J16: 0.072 | K16: 0.07
D17: Bear Case | E17: 0.056 | F17: 0.058 | G17: 0.06 | H17: 0.061 | I17: 0.062 | J17: 0.062 | K17: 0.062
D18: Stress Case | E18: 0.044 | F18: 0.048 | G18: 0.055 | H18: 0.058 | I18: 0.06 | J18: 0.06 | K18: 0.06
A19: D02 | B19: Steel demand elasticity to real GDP | C19: x | D19: Base Case | E19: 1.15 | F19: 1.15 | G19: 1.12 | H19: 1.1 | I19: 1.08 | J19: 1.06 | K19: 1.05 | M19: Derived-DB | N19: High | O19: Realised elasticity FY2015-FY2026 is 1.06x to 1.13x: apparent consumption compounded at 7.13% (76.99 Mt to 164.19 Mt over 11 years) against real GDP CAGR of roughly 6.3-6.7%, midpoint 1.10x. Near-term base is set slightly above at 1.15x because worldsteel's Apr-2026 Short Range Outlook forecasts Indian demand +7.4% in CY2026 and +9.2% in CY2027 against RBI GDP of 6.6%, implying 1.1x-1.4x. Elasticity tapers toward 1.05x by FY2033 on the standard maturing-intensity argument as per capita consumption rises from 115.7 kg. Stress assumes elasticity falls below 1.0x, as it did in FY2021 (-5.27% consumption on a positive-growth base effect).
D20: Bull Case | E20: 1.3 | F20: 1.28 | G20: 1.25 | H20: 1.22 | I20: 1.2 | J20: 1.18 | K20: 1.15
D21: Bear Case | E21: 1 | F21: 1 | G21: 0.98 | H21: 0.97 | I21: 0.96 | J21: 0.95 | K21: 0.95
D22: Stress Case | E22: 0.75 | F22: 0.85 | G22: 0.9 | H22: 0.92 | I22: 0.93 | J22: 0.94 | K22: 0.95
A23: D03 | B23: USD/INR average | C23: Rs/US$ | D23: Base Case | E23: 94.5 | F23: 95.5 | G23: 96.5 | H23: 97.5 | I23: 98.5 | J23: 99.5 | K23: 100.5 | M23: IDBI-22Jun26 | N23: High | O23: Spot USD/INR was 94 on 22-Jun-2026 with a 52-week range of 85 to 98 (IDBI Capital commodity tracker). Base assumes ~1.0% annual depreciation, consistent with the inflation differential implied by RBI's 5.1% FY2027 CPI projection against developed-market targets of ~2%. Stress takes INR beyond the 52-week low to 113, a ~20% depreciation from spot. MATERIAL BOTH WAYS: a weaker INR raises rupee raw-material cost (iron ore, coking coal and nickel are dollar-priced) but also raises the rupee landed cost of imports, supporting domestic realisations.
D24: Bull Case | E24: 93 | F24: 93.5 | G24: 94 | H24: 94.5 | I24: 95 | J24: 95.5 | K24: 96
D25: Bear Case | E25: 96.5 | F25: 98.5 | G25: 100 | H25: 101.5 | I25: 103 | J25: 104.5 | K25: 106
D26: Stress Case | E26: 101 | F26: 105 | G26: 107 | H26: 108.5 | I26: 110 | J26: 111.5 | K26: 113
A27: D04 | B27: CPI inflation | C27: % | D27: Base Case | E27: 0.051 | F27: 0.046 | G27: 0.045 | H27: 0.045 | I27: 0.045 | J27: 0.045 | K27: 0.045 | M27: RBI-Jun26 | N27: High | O27: RBI raised its FY2027 CPI projection by 50bps to 5.1% at the 05-Jun-2026 MPC, citing crude oil and supply disruption. Base converges to the 4.5% mid-point of the RBI's 4%+/-2% target band. Drives conversion cost inflation (D12) and the discount rate.
D28: Bull Case | E28: 0.045 | F28: 0.042 | G28: 0.042 | H28: 0.042 | I28: 0.042 | J28: 0.042 | K28: 0.042
D29: Bear Case | E29: 0.057 | F29: 0.052 | G29: 0.05 | H29: 0.048 | I29: 0.048 | J29: 0.048 | K29: 0.048
D30: Stress Case | E30: 0.068 | F30: 0.062 | G30: 0.055 | H30: 0.052 | I30: 0.05 | J30: 0.05 | K30: 0.05
A31: D05 | B31: Announced pipeline delivery factor | C31: % | D31: Base Case | E31: 0.85 | F31: 0.85 | G31: 0.85 | H31: 0.85 | I31: 0.85 | J31: 0.85 | K31: 0.85 | M31: Derived-DB | N31: Medium | O31: Proportion of dated announced capacity additions assumed to commission on schedule. Calibrated against realised delivery: India added 20.82 Mtpa in FY2025 and 20.07 Mtpa in FY2026 (Master DB), against a National Steel Policy path to 300 Mtpa by FY2031 that requires roughly 16 Mtpa a year - i.e. recent delivery has RUN AHEAD of the required rate, which supports a base factor materially above 50%. 85% rather than 100% reflects the routine slippage evident in the tracker (JSW Vijayanagar BF-3 was still under testing at FY2026 year-end; AM/NS Hazira 9 to 15 Mtpa has been in progress for several years). Stress at 55% reflects a capital-constrained environment.
D32: Bull Case | E32: 0.95 | F32: 0.95 | G32: 0.95 | H32: 0.95 | I32: 0.95 | J32: 0.95 | K32: 0.95
D33: Bear Case | E33: 0.7 | F33: 0.7 | G33: 0.7 | H33: 0.7 | I33: 0.7 | J33: 0.7 | K33: 0.7
D34: Stress Case | E34: 0.55 | F34: 0.55 | G34: 0.55 | H34: 0.55 | I34: 0.55 | J34: 0.55 | K34: 0.55
A35: D06 | B35: Crude-to-finished steel ratio | C35: x | D35: Base Case | E35: 1.0465 | F35: 1.0465 | G35: 1.0465 | H35: 1.0465 | I35: 1.0465 | J35: 1.0465 | K35: 1.0465 | M35: Derived-DB | N35: High | O35: FY2026 actual 168.42 / 160.94 = 1.0465 on the April-2026 JPC vintage used throughout the model (Master DB). Held flat in the base case: yield improvement is slow and offsetting mix effects are material. Bull assumes modest yield gains from continuous casting and newer assets; bear and stress assume yield deterioration from higher utilisation of older assets.
D36: Bull Case | E36: 1.043 | F36: 1.043 | G36: 1.043 | H36: 1.043 | I36: 1.043 | J36: 1.043 | K36: 1.043
D37: Bear Case | E37: 1.05 | F37: 1.05 | G37: 1.05 | H37: 1.05 | I37: 1.05 | J37: 1.05 | K37: 1.05
D38: Stress Case | E38: 1.053 | F38: 1.053 | G38: 1.053 | H38: 1.053 | I38: 1.053 | J38: 1.053 | K38: 1.053
A39: D07 | B39: Net finished steel exports | C39: Mt | D39: Base Case | E39: 0.5 | F39: 1 | G39: 1.5 | H39: 2 | I39: 2.5 | J39: 3 | K39: 3.5 | M39: Derived-DB | N39: Medium | O39: FY2026 actual net exports +0.078 Mt, having swung 4.77 Mt from a 4.693 Mt net import position in FY2025 (Master DB). Base assumes India becomes a progressively larger net exporter as capacity growth outpaces demand growth. Bear case is HIGHER net exports, because weak domestic demand forces surplus tonnes offshore at lower realisations. Stress reverses the sign: a demand collapse in India combined with the safeguard duty lapsing in Apr-2028 makes India a net importer again, which is the historically observed FY2025 configuration.
D40: Bull Case | E40: 0 | F40: 0 | G40: 0.5 | H40: 0.5 | I40: 1 | J40: 1 | K40: 1.5
D41: Bear Case | E41: 1.5 | F41: 2.5 | G41: 3.5 | H41: 4.5 | I41: 5.5 | J41: 6 | K41: 6.5
D42: Stress Case | E42: -1 | F42: -2.5 | G42: -3.5 | H42: -4 | I42: -4.5 | J42: -5 | K42: -5
...

Sheet 03 Macroeconomic Model
B1: 03 Macroeconomic Model
B2: Industry Financial Model | Indian Steel Industry | Horizon FY2027E-FY2033E | Base year FY2026A | Built 03-Aug-2026
B4: OBJECTIVE
B5: The macro spine: real GDP, inflation, the exchange rate and interest rates. Every demand and cost forecast in the workbook is anchored here.
B6: METHODOLOGY
B7: Real GDP growth and CPI are taken from RBI's June-2026 Monetary Policy Committee projections for FY2027 and converge to a steady state thereafter, because no Indian official body publishes a real GDP path beyond roughly five years. USD/INR is anchored on the 22-Jun-2026 spot of 94. Index rows compound the growth rates so that cumulative effects are visible rather than implied.
B8: UNITS
B9: Percentages as decimals. Indices FY2026A = 100. USD/INR in rupees per dollar.
B10: DEPENDENCIES
B11: Reads 02 Model Assumptions. Read by 04 Steel Demand, 10 Raw Material, 16 Cash Flow.
B13: Line item | C13: Unit | D13: FY2026A | E13: FY2027E | F13: FY2028E | G13: FY2029E | H13: FY2030E | I13: FY2031E | J13: FY2032E | K13: FY2033E | L13: CAGR | M13: Source | N13: Conf. | O13: Notes / methodology
B14: GROWTH AND PRICES
B15: India real GDP growth | C15: % | D15: 0.076 | E15: '02 Model Assumptions'!E$122 | F15: '02 Model Assumptions'!F$122 | G15: '02 Model Assumptions'!G$122 | H15: '02 Model Assumptions'!H$122 | I15: '02 Model Assumptions'!I$122 | J15: '02 Model Assumptions'!J$122 | K15: '02 Model Assumptions'!K$122 | M15: RBI MPC 05-Jun-2026 | N15: High | O15: FY2026A of 7.6% is the RBI's own estimate for FY2026. FY2027E of 6.6% is the RBI projection, revised down from 6.9% on West Asia conflict, energy prices and monsoon risk. Beyond FY2027 the path converges to 6.5%.
B16: Real GDP index | C16: FY2026A=100 | D16: 100 | E16: =D16*(1+E15) | F16: =E16*(1+F15) | G16: =F16*(1+G15) | H16: =G16*(1+H15) | I16: =H16*(1+I15) | J16: =I16*(1+J15) | K16: =J16*(1+K15) | L16: =IFERROR(IF(AND(ISNUMBER(D16),ISNUMBER(K16),D16>0),(K16/D16)^(1/7)-1,""),"") | M16: Computed | N16: High | O16: Compounds the growth rate above.
B17: CPI inflation | C17: % | D17: 0.051 | E17: '02 Model Assumptions'!E$125 | F17: '02 Model Assumptions'!F$125 | G17: '02 Model Assumptions'!G$125 | H17: '02 Model Assumptions'!H$125 | I17: '02 Model Assumptions'!I$125 | J17: '02 Model Assumptions'!J$125 | K17: '02 Model Assumptions'!K$125 | M17: RBI MPC 05-Jun-2026 | N17: High | O17: RBI raised its FY2027 CPI projection by 50bps to 5.1%. Converges to the 4.5% mid-point of the 4% plus or minus 2% target band.
B18: Nominal GDP index | C18: FY2026A=100 | D18: 100 | E18: =D18*(1+E15)*(1+E17) | F18: =E18*(1+F15)*(1+F17) | G18: =F18*(1+G15)*(1+G17) | H18: =G18*(1+H15)*(1+H17) | I18: =H18*(1+I15)*(1+I17) | J18: =I18*(1+J15)*(1+J17) | K18: =J18*(1+K15)*(1+K17) | L18: =IFERROR(IF(AND(ISNUMBER(D18),ISNUMBER(K18),D18>0),(K18/D18)^(1/7)-1,""),"") | M18: Computed | N18: High | O18: Real growth compounded with inflation.
B20: EXCHANGE RATE AND INTEREST RATES
B21: USD/INR (average) | C21: Rs/US$ | D21: 88.4 | E21: '02 Model Assumptions'!E$124 | F21: '02 Model Assumptions'!F$124 | G21: '02 Model Assumptions'!G$124 | H21: '02 Model Assumptions'!H$124 | I21: '02 Model Assumptions'!I$124 | J21: '02 Model Assumptions'!J$124 | K21: '02 Model Assumptions'!K$124 | L21: =IFERROR(IF(AND(ISNUMBER(D21),ISNUMBER(K21),D21>0),(K21/D21)^(1/7)-1,""),"") | M21: IDBI Capital 22-Jun-2026 | N21: High | O21: FY2026A of 88.4 is DERIVED from Tata Steel's dual-currency disclosure in the database - consolidated EBITDA/t of Rs 10,900 against US$124 gives 87.90, India EBITDA/t of Rs 15,213 against US$172 gives 88.45, and group turnover of Rs 2,32,140 cr against US$26bn gives 89.28. Spot was 94 on 22-Jun-2026 with a 52-week range of 85 to 98.
B22: INR depreciation | C22: % | E22: =E21/D21-1 | F22: =F21/E21-1 | G22: =G21/F21-1 | H22: =H21/G21-1 | I22: =I21/H21-1 | J22: =J21/I21-1 | K22: =K21/J21-1 | M22: Computed | N22: High | O22: Positive equals depreciation, which raises rupee raw-material cost but also raises the rupee landed cost of imports and therefore supports domestic realisations.
B23: 10-year G-sec yield | C23: % | D23: 0.0683 | E23: ='02 Model Assumptions'!$D$164 | F23: ='02 Model Assumptions'!$D$164 | G23: ='02 Model Assumptions'!$D$164 | H23: ='02 Model Assumptions'!$D$164 | I23: ='02 Model Assumptions'!$D$164 | J23: ='02 Model Assumptions'!$D$164 | K23: ='02 Model Assumptions'!$D$164 | M23: investing.com 31-Jul-2026 | N23: High | O23: 6.833% on 31-Jul-2026. Trading Economics expects 6.78% at quarter end. Held flat across the horizon - a term-structure forecast is not attempted.
B24: WACC (nominal, INR) | C24: % | E24: '02 Model Assumptions'!E$141 | F24: '02 Model Assumptions'!F$141 | G24: '02 Model Assumptions'!G$141 | H24: '02 Model Assumptions'!H$141 | I24: '02 Model Assumptions'!I$141 | J24: '02 Model Assumptions'!J$141 | K24: '02 Model Assumptions'!K$141 | M24: Composite - see 02 Section D | N24: Medium | O24: Used for discounting on 23 Comparable Valuation. Cross-checked against the build-up on 02 Section D by 25 Audit Checks.
B26: Macro drivers are scenario-dependent: the stress case applies a 220bps FY2027 GDP shock and takes USD/INR beyond its 52-week low.

Sheet 04 Steel Demand Model
B1: 04 Steel Demand Model
B2: Industry Financial Model | Indian Steel Industry | Horizon FY2027E-FY2033E | Base year FY2026A | Built 03-Aug-2026
B4: OBJECTIVE
B5: Forecasts India's apparent finished steel consumption, the demand anchor for the whole model.
B6: METHODOLOGY
B7: Consumption growth equals real GDP growth multiplied by a steel demand elasticity. The elasticity is not assumed - it is calibrated to realised history: consumption compounded at 7.13% from 76.99 Mt in FY2015 to 164.19 Mt in FY2026 against real GDP CAGR of roughly 6.3-6.7%, giving 1.06x to 1.13x. It is set at 1.15x near term, consistent with worldsteel's Apr-2026 forecast of +7.4% in CY2026 and +9.2% in CY2027 against RBI GDP of 6.6%, then tapers to 1.05x on maturing intensity.
B8: UNITS
B9: Mt. Population in billions. Per capita in kg.
B10: DEPENDENCIES
B11: Reads 03 Macroeconomic Model and 02 Model Assumptions. Read by 05 Steel Supply.
B13: Line item | C13: Unit | D13: FY2026A | E13: FY2027E | F13: FY2028E | G13: FY2029E | H13: FY2030E | I13: FY2031E | J13: FY2032E | K13: FY2033E | L13: CAGR | M13: Source | N13: Conf. | O13: Notes / methodology
B14: India real GDP growth | C14: % | D14: 0.076 | E14: ='03 Macroeconomic Model'!E$15 | F14: ='03 Macroeconomic Model'!F$15 | G14: ='03 Macroeconomic Model'!G$15 | H14: ='03 Macroeconomic Model'!H$15 | I14: ='03 Macroeconomic Model'!I$15 | J14: ='03 Macroeconomic Model'!J$15 | K14: ='03 Macroeconomic Model'!K$15 | M14: 03 Macro | N14: High | O14: Linked, not re-entered.
B15: Steel demand elasticity to GDP | C15: x | D15: 1.1 | E15: '02 Model Assumptions'!E$123 | F15: '02 Model Assumptions'!F$123 | G15: '02 Model Assumptions'!G$123 | H15: '02 Model Assumptions'!H$123 | I15: '02 Model Assumptions'!I$123 | J15: '02 Model Assumptions'!J$123 | K15: '02 Model Assumptions'!K$123 | M15: Derived from Master DB | N15: High | O15: FY2026A of 1.10x is the realised FY2015-FY2026 average, the midpoint of the 1.06x-1.13x range depending on the GDP deflator used.
B16: Implied consumption growth | C16: % | D16: 0.079 | E16: =E14*E15 | F16: =F14*F15 | G16: =G14*G15 | H16: =H14*H15 | I16: =I14*I15 | J16: =J14*J15 | K16: =K14*K15 | M16: Computed | N16: High | O16: FY2026A of 7.9% is the actual reported growth, against 7.6% GDP times 1.04x realised elasticity - the model's structure reproduces the actual outturn.
B17: Apparent finished steel consumption | C17: Mt | D17: 163.74 | E17: =D17*(1+E16) | F17: =E17*(1+F16) | G17: =F17*(1+G16) | H17: =G17*(1+H16) | I17: =H17*(1+I16) | J17: =I17*(1+J16) | K17: =J17*(1+K16) | L17: =IFERROR(IF(AND(ISNUMBER(D17),ISNUMBER(K17),D17>0),(K17/D17)^(1/7)-1,""),"") | M17: 00 Database Import A03 | N17: High | O17: FY2026A of 163.74 Mt is the April-2026 JPC vintage, which is the internally self-reconciling balance. The June-2026 vintage of 164.19 Mt is a memo below.
B18: Memo: June-2026 JPC vintage, FY2026 actual | C18: Mt | D18: 164.19 | M18: Master DB | N18: High | O18: Carried so the vintage difference is visible rather than buried - Master DB Conflict C03. The 0.45 Mt difference is 0.27%.
B20: DEMAND INTENSITY
B21: Population | C21: bn | D21: 1.4191 | E21: =D21*(1+$D$22) | F21: =E21*(1+$D$22) | G21: =F21*(1+$D$22) | H21: =G21*(1+$D$22) | I21: =H21*(1+$D$22) | J21: =I21*(1+$D$22) | K21: =J21*(1+$D$22) | M21: Derived | N21: Medium | O21: DERIVED from the database: consumption of 163.74 Mt divided by per capita consumption of 115.7 kg gives 1.4152 bn; the 1.4191 bn shown uses the June-vintage consumption of 164.19 Mt against 115.7 kg, which is the internally consistent pairing the database publishes.
B22: Population growth | C22: % | D22: 0.0085 | M22: NOT SOURCED | N22: Low | O22: 0.85% per annum is NOT sourced in this research cycle. Replace with a UN World Population Prospects series. Affects per capita consumption only, not tonnage, so it does not propagate into revenue or EBITDA.
B23: Per capita finished steel consumption | C23: kg | D23: 115.7 | E23: =E17/E21 | F23: =F17/F21 | G23: =G17/G21 | H23: =H17/H21 | I23: =I17/I21 | J23: =J17/J21 | K23: =K17/K21 | L23: =IFERROR(IF(AND(ISNUMBER(D23),ISNUMBER(K23),D23>0),(K23/D23)^(1/7)-1,""),"") | M23: Computed | N23: Medium | O23: Consumption in Mt divided by population in bn gives kg per head directly. India is at roughly half the world average of 215 kg and about a fifth of China's 604 kg.
B25: Demand is the ONLY block in this model that is not capacity-aware. The capacity ceiling is applied on 05 Steel Supply, so consumption here is unconstrained demand.

Sheet 05 Steel Supply Model
B1: 05 Steel Supply Model
B2: Industry Financial Model | Indian Steel Industry | Horizon FY2027E-FY2033E | Base year FY2026A | Built 03-Aug-2026
B4: OBJECTIVE
B5: Converts demand into required domestic production, applies a practical capacity ceiling, and routes any shortfall to imports so that the supply balance always closes.
B6: METHODOLOGY
B7: The identity is the Joint Plant Committee's own: consumption equals production plus imports less exports adjusted for the change in stocks. Rearranged, required finished production equals consumption plus net exports plus the stock change. Crude steel equals finished production multiplied by the crude-to-finished ratio of 1.0465, which is the FY2026 actual on the April-2026 vintage. Production is then capped at capacity times maximum practical utilisation of 92%; where demand would exceed that, the shortfall is met by additional imports rather than by impossible domestic output.
B8: UNITS
B9: Mt. Ratio in times.
B10: DEPENDENCIES
B11: Reads 04 Steel Demand, 06 Capacity Forecast, 02 Model Assumptions. Read by 09, 11, 12, 13, 19.
B13: Line item | C13: Unit | D13: FY2026A | E13: FY2027E | F13: FY2028E | G13: FY2029E | H13: FY2030E | I13: FY2031E | J13: FY2032E | K13: FY2033E | L13: CAGR | M13: Source | N13: Conf. | O13: Notes / methodology
B14: Apparent finished steel consumption | C14: Mt | D14: 163.74 | E14: ='04 Steel Demand Model'!E$17 | F14: ='04 Steel Demand Model'!F$17 | G14: ='04 Steel Demand Model'!G$17 | H14: ='04 Steel Demand Model'!H$17 | I14: ='04 Steel Demand Model'!I$17 | J14: ='04 Steel Demand Model'!J$17 | K14: ='04 Steel Demand Model'!K$17 | M14: 04 Demand | N14: High
B15: Net finished steel exports | C15: Mt | D15: 0.078 | E15: '02 Model Assumptions'!E$128 | F15: '02 Model Assumptions'!F$128 | G15: '02 Model Assumptions'!G$128 | H15: '02 Model Assumptions'!H$128 | I15: '02 Model Assumptions'!I$128 | J15: '02 Model Assumptions'!J$128 | K15: '02 Model Assumptions'!K$128 | M15: Derived from Master DB | N15: Medium | O15: FY2026A of +0.078 Mt - India returned to net exporter status having been 4.693 Mt net importer in FY2025, a 4.77 Mt swing in one year.
B16: Variation in stock | C16: Mt | D16: -2.88 | E16: '02 Model Assumptions'!E$129 | F16: '02 Model Assumptions'!F$129 | G16: '02 Model Assumptions'!G$129 | H16: '02 Model Assumptions'!H$129 | I16: '02 Model Assumptions'!I$129 | J16: '02 Model Assumptions'!J$129 | K16: '02 Model Assumptions'!K$129 | M16: Master DB supply balance | N16: Medium | O16: FY2026A of -2.88 Mt, i.e. a DESTOCK of about 1.8% of consumption which flattered reported consumption growth. Base normalises to a small restock.
B17: Required finished steel production | C17: Mt | D17: 160.94 | E17: =E14+E15+E16 | F17: =F14+F15+F16 | G17: =G14+G15+G16 | H17: =H14+H15+H16 | I17: =I14+I15+I16 | J17: =J14+J15+J16 | K17: =K14+K15+K16 | M17: Computed - JPC identity | N17: High | O17: IDENTITY CHECK: 163.74 + 0.078 + (-2.88) = 160.94, which equals the reported FY2026 finished steel production exactly. The balance closes.
B18: Crude-to-finished steel ratio | C18: x | D18: 1.04647 | E18: '02 Model Assumptions'!E$127 | F18: '02 Model Assumptions'!F$127 | G18: '02 Model Assumptions'!G$127 | H18: '02 Model Assumptions'!H$127 | I18: '02 Model Assumptions'!I$127 | J18: '02 Model Assumptions'!J$127 | K18: '02 Model Assumptions'!K$127 | M18: Derived from Master DB | N18: High | O18: 168.42 / 160.94 on the April-2026 vintage. On the June vintage it would be 1.0413, a 0.5% difference.
B19: Required crude steel production (unconstrained) | C19: Mt | D19: 168.42 | E19: =E17*E18 | F19: =F17*F18 | G19: =G17*G18 | H19: =H17*H18 | I19: =I17*I18 | J19: =J17*J18 | K19: =K17*K18 | M19: Computed | N19: High
B21: CAPACITY CEILING
B22: Crude steel capacity | C22: Mtpa | D22: 220.4 | E22: ='06 Capacity Forecast'!E$20 | F22: ='06 Capacity Forecast'!F$20 | G22: ='06 Capacity Forecast'!G$20 | H22: ='06 Capacity Forecast'!H$20 | I22: ='06 Capacity Forecast'!I$20 | J22: ='06 Capacity Forecast'!J$20 | K22: ='06 Capacity Forecast'!K$20 | M22: 06 Capacity | N22: High
B23: Maximum practical utilisation | C23: % | E23: '02 Model Assumptions'!E$146 | F23: '02 Model Assumptions'!F$146 | G23: '02 Model Assumptions'!G$146 | H23: '02 Model Assumptions'!H$146 | I23: '02 Model Assumptions'!I$146 | J23: '02 Model Assumptions'!J$146 | K23: '02 Model Assumptions'!K$146 | M23: Indicative | N23: Low | O23: 92%. Allows for maintenance and relining. Individual assets can exceed nameplate - the database records SAIL Rourkela at 103.8% - but a national aggregate cannot.
B24: Maximum crude steel production | C24: Mt | E24: =E22*E23 | F24: =F22*F23 | G24: =G22*G23 | H24: =H22*H23 | I24: =I22*I23 | J24: =J22*J23 | K24: =K22*K23 | M24: Computed | N24: Low
B25: Crude steel production | C25: Mt | D25: 168.42 | E25: =MIN(E19,E24) | F25: =MIN(F19,F24) | G25: =MIN(G19,G24) | H25: =MIN(H19,H24) | I25: =MIN(I19,I24) | J25: =MIN(J19,J24) | K25: =MIN(K19,K24) | L25: =IFERROR(IF(AND(ISNUMBER(D25),ISNUMBER(K25),D25>0),(K25/D25)^(1/7)-1,""),"") | M25: Computed | N25: High | O25: The binding constraint. In the base case the ceiling does NOT bind - peak utilisation is 84.0% in FY2033 - which is itself an important finding: India is not capacity-constrained on this demand path.
B26: Capacity ceiling binding? | C26: flag | E26: =IF(E19>E24+0.001,"BINDING","no") | F26: =IF(F19>F24+0.001,"BINDING","no") | G26: =IF(G19>G24+0.001,"BINDING","no") | H26: =IF(H19>H24+0.001,"BINDING","no") | I26: =IF(I19>I24+0.001,"BINDING","no") | J26: =IF(J19>J24+0.001,"BINDING","no") | K26: =IF(K19>K24+0.001,"BINDING","no") | M26: Computed | N26: High | O26: Flags any year where domestic demand cannot be met from domestic capacity.
B27: Finished steel production | C27: Mt | D27: 160.94 | E27: =E25/E18 | F27: =F25/F18 | G27: =G25/G18 | H27: =H25/H18 | I27: =I25/I18 | J27: =J25/J18 | K27: =K25/K18 | L27: =IFERROR(IF(AND(ISNUMBER(D27),ISNUMBER(K27),D27>0),(K27/D27)^(1/7)-1,""),"") | M27: Computed | N27: High
B28: Shortfall met by additional imports | C28: Mt | D28: 0 | E28: =MAX(0,E17-E27) | F28: =MAX(0,F17-F27) | G28: =MAX(0,G17-G27) | H28: =MAX(0,H17-H27) | I28: =MAX(0,I17-I27) | J28: =MAX(0,J17-J27) | K28: =MAX(0,K17-K27) | M28: Computed | N28: High | O28: Keeps the balance closed when the ceiling binds. Flows through to 19 Trade Model.
B30: The model does NOT endogenise supply response - it does not idle capacity when margins turn negative. This is why the stress case should be read as a lower bound on margin rather than a central expectation, and is a documented limitation on 25 Audit Checks.

Sheet 06 Capacity Forecast
B1: 06 Capacity Forecast
B2: Industry Financial Model | Indian Steel Industry | Horizon FY2027E-FY2033E | Base year FY2026A | Built 03-Aug-2026
B4: OBJECTIVE
B5: Forecasts India's crude steel capacity from the dated project pipeline plus a secondary-sector residual, and validates the result against the National Steel Policy 2017 target.
B6: METHODOLOGY
B7: Capacity equals prior-year capacity plus announced additions delivered plus secondary and unattributed additions. Announced additions come live from the project tracker by SUMIFS and are multiplied by a delivery factor of 85% reflecting observed slippage. The secondary residual exists because the tracker captures only individually announced projects averaging 7.7 Mtpa a year, whereas India actually added 20.8 Mtpa in FY2025 and 20.1 Mtpa in FY2026 - the difference comes from the secondary sector, whose output the database shows growing at 10.7% a year, faster than the integrated majors' 8.1%.
B8: UNITS
B9: Mtpa.
B10: DEPENDENCIES
B11: Reads 07 Capacity Expansion Tracker and 02 Model Assumptions. Read by 08 Utilisation, 05 Steel Supply, 17 Capital Allocation.
B13: Line item | C13: Unit | D13: FY2026A | E13: FY2027E | F13: FY2028E | G13: FY2029E | H13: FY2030E | I13: FY2031E | J13: FY2032E | K13: FY2033E | L13: CAGR | M13: Source | N13: Conf. | O13: Notes / methodology
B14: Opening capacity | C14: Mtpa | E14: =D20 | F14: =E20 | G14: =F20 | H14: =G20 | I14: =H20 | J14: =I20 | K14: =J20 | M14: Computed | N14: High | O14: Prior-year closing capacity.
B15: Gross announced additions (from tracker) | C15: Mtpa | E15: ='07 Capacity Expansion Tracker'!E$36 | F15: ='07 Capacity Expansion Tracker'!F$36 | G15: ='07 Capacity Expansion Tracker'!G$36 | H15: ='07 Capacity Expansion Tracker'!H$36 | I15: ='07 Capacity Expansion Tracker'!I$36 | J15: ='07 Capacity Expansion Tracker'!J$36 | K15: ='07 Capacity Expansion Tracker'!K$36 | M15: 07 Tracker (SUMIFS) | N15: Medium | O15: Live from the project tracker. Excludes acquisitions, downstream lines, overseas assets and already-commissioned projects.
B16: Pipeline delivery factor | C16: % | E16: '02 Model Assumptions'!E$126 | F16: '02 Model Assumptions'!F$126 | G16: '02 Model Assumptions'!G$126 | H16: '02 Model Assumptions'!H$126 | I16: '02 Model Assumptions'!I$126 | J16: '02 Model Assumptions'!J$126 | K16: '02 Model Assumptions'!K$126 | M16: Derived from Master DB | N16: Medium | O16: 85% in the base case. India delivered ~20 Mtpa a year in FY2025 and FY2026 against a National Steel Policy requirement of ~16 Mtpa a year, so delivery capability is demonstrated; the 15% haircut reflects project-level slippage such as JSW Vijayanagar BF-3 still testing at FY2026 year-end.
B17: Announced additions delivered | C17: Mtpa | E17: =E15*E16 | F17: =F15*F16 | G17: =G15*G16 | H17: =H15*H16 | I17: =I15*I16 | J17: =J15*J16 | K17: =K15*K16 | M17: Computed | N17: Medium
B18: Secondary and unattributed additions | C18: Mtpa | E18: '02 Model Assumptions'!E$143 | F18: '02 Model Assumptions'!F$143 | G18: '02 Model Assumptions'!G$143 | H18: '02 Model Assumptions'!H$143 | I18: '02 Model Assumptions'!I$143 | J18: '02 Model Assumptions'!J$143 | K18: '02 Model Assumptions'!K$143 | M18: Derived from Master DB | N18: Medium | O18: ESSENTIAL RECONCILIATION ITEM. Omitting this would understate FY2031 capacity by about 54 Mtpa, or 18%.
B19: Total additions | C19: Mtpa | D19: 20.07 | E19: =E17+E18 | F19: =F17+F18 | G19: =G17+G18 | H19: =H17+H18 | I19: =I17+I18 | J19: =J17+J18 | K19: =K17+K18 | M19: Computed | N19: Medium | O19: FY2026A of 20.07 Mtpa is the actual year-on-year capacity increase from the database (220.4 less 200.33).
B20: Closing crude steel capacity | C20: Mtpa | D20: 220.4 | E20: =D20+E19 | F20: =E20+F19 | G20: =F20+G19 | H20: =G20+H19 | I20: =H20+I19 | J20: =I20+J19 | K20: =J20+K19 | L20: =IFERROR(IF(AND(ISNUMBER(D20),ISNUMBER(K20),D20>0),(K20/D20)^(1/7)-1,""),"") | M20: 00 Database Import A04 | N20: High | O20: FY2026A of 220.4 Mtpa is the database figure (June-2026 Ministry vintage; the March vintage said 220.3 - Conflict C04).
B22: VALIDATION AGAINST NATIONAL STEEL POLICY 2017
B23: National Steel Policy 2017 target | C23: Mtpa | I23: 300 | M23: Master DB policy P10 | N23: High | O23: 300 Mtpa of crude steel capacity by FY2031.
B24: Model capacity in FY2031E | C24: Mtpa | I24: =I20 | M24: Computed | N24: High
B25: Model as % of policy target | C25: % | I25: =I24/I23 | M25: Computed | N25: High | O25: The model was built bottom-up from the project tracker plus the secondary residual and was NOT calibrated to the policy target, so agreement within roughly 1% is a genuine independent check on the capacity block.
B27: Sign warning: more capacity is EBITDA-NEGATIVE in this model, because it depresses utilisation which feeds back into price via driver D23. See 09 Steel Price Forecast.

Sheet 07 Capacity Expansion Tracker
B1: 07 Capacity Expansion Tracker
B2: Industry Financial Model | Indian Steel Industry | Horizon FY2027E-FY2033E | Base year FY2026A | Built 03-Aug-2026
B4: OBJECTIVE
B5: The dated project pipeline that drives the capacity forecast. Twenty projects, each with its capacity, status, expected commissioning year and whether it counts towards INDIA's national crude steel capacity.
B6: METHODOLOGY
B7: Every project is taken from the Master Database. The 'Included in forecast' flag is the critical field and encodes four exclusions that are routinely got wrong: already-commissioned projects are in the FY2026 base and must not be added again; ACQUISITIONS add to a company but nothing to national capacity; DOWNSTREAM lines (HRAP, CRAP, cold rolling) are processing capacity, not melt capacity; and OVERSEAS assets are outside India. Ramp-ups are utilisation, not capacity. 06 Capacity Forecast reads this sheet by SUMIFS on the flag and the year, so changing a flag or a date here immediately changes the forecast.
B8: UNITS
B9: Mtpa. Capex in Rs crore.
B10: DEPENDENCIES
B11: Source: Master Industry Database. Read by 06 Capacity Forecast and 12 Revenue.
A13: Project ID | B13: Company | C13: Project / Asset | D13: State / Country | E13: Type | F13: Capacity Added (Mtpa) | G13: Capacity Definition | H13: Status At Cutoff | I13: Expected Commissioning FY | J13: Capex (Rs cr) | K13: Implied Capex (Rs/t) | L13: Included In Forecast? | M13: Source ID | N13: Confidence | O13: Notes
A14: P01 | B14: Tata Steel | C14: Ludhiana scrap-based EAF | D14: Punjab | E14: Brownfield EAF | F14: 0.75 | G14: Crude steel | H14: Commissioned Mar-2026 | I14: FY2026 | J14: 3200 | K14: =J14/F14*10000 | L14: No - already in base | M14: S08 | N14: High | O14: Commissioned in Mar-2026 and therefore already inside the FY2026 capacity base of 220.4 Mtpa. Designed for under 0.3 tCO2e per tonne of crude steel, which makes it 5-star green steel under the Taxonomy notified 23-Dec-2024.
A15: P02 | B15: Tata Steel | C15: NINL expansion | D15: Odisha | E15: Brownfield integrated | F15: 4.8 | G15: Crude steel | H15: Proposed | I15: FY2030 | L15: Yes | M15: S08 | N15: Medium | O15: Described as proposed in the FY2026 results release, so not yet Board-approved capex. Commissioning year is the modeller's estimate based on typical 4-year build.
A16: P03 | B16: Tata Steel | C16: India roadmap to 40 Mtpa | D16: India | E16: Programme | F16: 5 | G16: Crude steel | H16: Announced - aspirational | I16: FY2033 | L16: Yes | M16: S37 | N16: Low | O16: Tata Steel's Q1FY2027 presentation (31-Jul-2026) sets out an India roadmap to 40 Mtpa. The residual above identified projects is carried at low confidence and is materially reduced by the delivery factor D05.
A17: P04 | B17: JSW Steel | C17: Vijayanagar BF-3 expansion 3.0 to 4.5 Mtpa | D17: Karnataka | E17: Brownfield BF | F17: 1.5 | G17: Crude steel | H17: Under testing and commissioning | I17: FY2027 | L17: Yes | M17: S09 | N17: High | O17: Was under testing at FY2026 year-end and excluded from the FY2026 utilisation calculation, so it is genuinely incremental to the base.
A18: P05 | B18: JSW Steel | C18: JVML-Vijayanagar brownfield expansion | D18: Karnataka | E18: Brownfield integrated | F18: 5 | G18: Crude steel | H18: Board approved | I18: FY2030 | J18: 26000 | K18: =J18/F18*10000 | L18: Yes | M18: S09 | N18: High | O18: Board approved. Rs 26,000 cr for 5 Mtpa gives Rs 52,000 per tonne, the cleanest brownfield capex-intensity datapoint available and the primary calibration for D16.
